Workbook

Sheet Dashboard
A1: Metric | B1: Value
A2: Portfolio Name | B2: IOS v3.1
A3: As of Date | B3: July 2026 Baseline
A4: Total Universe | B4: 35
A5: Core Holdings | B5: 4
A6: Bench | B6: 1
A7: Research | B7: 26
A8: Deferred | B8: 4
A9: Cash Allocation Target | B9: 20%
A10: Review Frequency | B10: Quarterly
A11: Total Portfolio Value (Rs) | B11: 70000
A12: Required Margin of Safety (%) | B12: 25
A13: Default Growth Rate if Missing (%) | B13: 8
A14: Cost of Equity Ke (%) | B14: 13
A15: India 10Y G-Sec Yield Ref (%) | B15: 6.7
A16: Valuation Model | B16: Justified P/E (ROE-based): PE = (1 - g/ROE) x 100/(Ke-g); IV = Implied EPS x Justified PE
A17: Note | B17: Current Price values are manual snapshots entered in Master Universe - refresh periodically, not live-linked

Sheet Master Universe
A1: S.No | B1: Company | C1: Ticker | D1: Sector | E1: Industry | F1: Market Cap | G1: IOS Stage | H1: Evidence Gate | I1: Business Score | J1: Investment Score | K1: Data Confidence (%) | L1: Business Confidence (%) | M1: Research Priority | N1: Event Overlay | O1: Business Quality Notes | P1: Valuation (P/E) | Q1: PEG | R1: PEGY | S1: EV/EBIT | T1: ROE % | U1: ROCE % | V1: Debt/Equity | W1: FCF Yield % | X1: Revenue Growth % | Y1: EPS Growth % | Z1: Capital Allocation Score [DEPRECATED - see Legacy Scores (Archived) sheet] | AA1: Management Score [DEPRECATED - see Legacy Scores (Archived) sheet] | AB1: Moat Score [DEPRECATED - see Legacy Scores (Archived) sheet] | AC1: Growth Score [DEPRECATED - see Legacy Scores (Archived) sheet] | AD1: Risk Score [DEPRECATED - see Legacy Scores (Archived) sheet] | AE1: Decision Journal | AF1: Last Reviewed | AG1: Next Review | AH1: Buy Price | AI1: Current Price | AJ1: Intrinsic Value | AK1: Margin of Safety % | AL1: Target Allocation % | AM1: Position Size (₹) | AN1: Status | AO1: Catalyst | AP1: Thesis Maturity | AQ1: Remarks | AR1: Investment Thesis | AS1: Key Risks | AT1: Valuation Summary | AU1: Upgrade/Downgrade Trigger | AV1: Sources Verified | AW1: EPS Implied (Rs, Price/PE) | AX1: Growth Rate Used % | AY1: Justified P/E | AZ1: Dividend Yield | BA1: Beta | BB1: P/E | BC1: P/B | BD1: Investment Confidence (%) | BE1: Risk Score (Engine) | BF1: Risk Confidence (%) | BG1: Portfolio Weight | BH1: Valuation Status | BI1: Overall Recommendation | BL1: Previous Close | BM1: Valuation Label
A2: 1 | B2: Computer Age Management Services (CAMS) | C2: CAMS.NS | D2: Financial Services | E2: RTA | F2: 186103906304 | G2: Core | H2: Pass | I2: 97 | J2: 46.141771 | K2: 97 | L2: 100 | M2: Low - thesis proven, maintenance only | N2: None | O2: Dominant mutual fund RTA | Debt/Equity ~0.05 (near-zero net cash). | P2: 40 | Q2: 2 | R2: 1.85 | S2: 31.503891 | T2: 36.031699 | U2: 41.205615 | V2: 0.05 | W2: 2.3775693 | X2: 16 | Y2: 20 | AE2: Complete | AF2: Jul-2026 | AG2: Oct-2026 | AH2: 229.35333 | AI2: 752 | AJ2: 286.69167 | AK2: -161.53533 | AL2: 4.5932617 | AM2: 45932.617 | AN2: Core | AO2: Market leadership | AP2: Validated | AQ2: See structured fields (Thesis / Risks / Valuation / Trigger / Sources) for detail. | AR2: Dominant RTA franchise (~65% mutual-fund AUM market share moat); high-margin, asset-light business compounding with AUM growth. | AS2: Regulatory/SEBI fee-structure changes; AUM-linked revenue exposed to market downturns. | AT2: P/E ~40x (near 10yr median); ROCE ~53-60%; ROE ~20-25%; net cash (~Rs.885M debt vs ~Rs.6.8B cash); gross margin ~65%, op margin ~40%. | AU2: Core holding, already promoted. Downgrade trigger: AUM market-share loss or regulatory fee cap. | AV2: Screener/GuruFocus aggregation, Jul-2026. | AW2: 19.100001 | AX2: 13.813758 | AY2: 15.010035 | AZ2: 1.61 | BB2: 39.256542 | BD2: 100 | BE2: 4.8623288 | BF2: 100 | BH2: OK | BI2: Watch (Quality, Pricey) | BM2: Extremely Overvalued
A3: 2 | B3: Tata Consultancy Services | C3: TCS.NS | D3: IT | E3: IT Services | F3: 7444214841344 | G3: Core | H3: Pass | I3: 74 | J3: 85.372053 | K3: 95 | L3: 100 | M3: Low - maintenance, USFDA/deal-win monitoring | N3: None | O3: High FCF and zero debt | P3: 18.6 | Q3: 2.33 | R3: 1.66 | S3: 11.198375 | T3: 45.364037 | U3: 55.181215 | V3: 0.11 | W3: 6.3884884 | X3: 6 | Y3: 8 | AE3: Complete | AF3: Jul-2026 | AG3: Oct-2026 | AH3: 2310.5072 | AI3: 1983 | AJ3: 2888.1341 | AK3: 28.760232 | AL3: 8.4985075 | AM3: 84985.075 | AN3: Core | AO3: AI & digital | AP3: Validated | AQ3: See structured fields (Thesis / Risks / Valuation / Trigger / Sources) for detail. | AR3: Largest Indian IT services franchise; AI-services growth narrative; deep valuation discount vs peers. | AS3: ROE/ROCE not independently re-verified this session (pending); global IT spending slowdown; stock down ~55% off ATH signals sentiment risk. | AT3: P/E ~18.6x vs Coforge ~36-38x; trading ~Rs.2,050-2,100 vs Aug-2024 ATH Rs.4,592. | AU3: Verify current ROE/ROCE from primary source. | AV3: Session verification, Jul-2026 (ROE/ROCE pending). | AW3: 136.04 | AX3: 25 | AY3: 21.230036 | AZ3: 5.92 | BB3: 15.124228 | BD3: 100 | BE3: 10.401187 | BF3: 100 | BH3: OK | BI3: Strong Buy | BM3: Undervalued
A4: 3 | B4: Lupin | C4: LUPIN.NS | D4: Healthcare | E4: Pharma | F4: 1124334829568 | G4: Core | H4: Pass | I4: 94 | J4: 69.986379 | K4: 94 | L4: 100 | M4: Low - minor pipeline monitoring | N4: None | O4: Turnaround | P4: 21 | Q4: 0.57 | R4: 0.56 | S4: 7.829358 | T4: 23.687436 | U4: 57.096423 | V4: 0.29 | W4: 4.5931155 | X4: 23 | Y4: 37 | AE4: Complete | AF4: Jul-2026 | AG4: Oct-2026 | AH4: 2080.3745 | AI4: 2476 | AJ4: 2600.4681 | AK4: 5.4401017 | AL4: 6.9669142 | AM4: 69669.142 | AN4: Core | AO4: USFDA compliance | AP4: Established | AQ4: See structured fields (Thesis / Risks / Valuation / Trigger / Sources) for detail. | AR4: Pharma turnaround story; margin expansion from product mix-shift; strengthening balance sheet. | AS4: ROE/P/E figure sourced from unverified ML screen; mix-shift durability unconfirmed. | AT4: ROCE 28.4%; revenue growth 23% (FY26); Q4 FY26 gross margin 75% (up from 61.7% YoY); net cash ~Rs.4,600cr. | AU4: Confirm ROE/P/E against primary source (currently ML-screen only). | AV4: FY26 results search this session, Jul-2026; ROE/P/E via ML Alpha screen (unverified). | AW4: 116.54 | AX4: 24.132888 | AY4: 22.313953 | AZ4: 0.48 | BB4: 21.100052 | BD4: 100 | BE4: 29.387782 | BF4: 100 | BH4: OK | BI4: Buy | BM4: Fair Value
A5: 4 | B5: Nesco | C5: NESCO.NS | D5: Real Estate | E5: Commercial | F5: 77266386944 | G5: Core | H5: Pass | I5: 45 | J5: 20.459665 | K5: 92 | L5: 100 | M5: Low - stable annuity economics | N5: None | O5: Asset-backed cash flow | P5: 19.8 | Q5: 1.24 | R5: 1.2 | T5: 13.774437 | U5: 12.944575 | V5: 0 | X5: 13 | Y5: 16 | AE5: Complete | AF5: Jul-2026 | AG5: Oct-2026 | AH5: 374.61282 | AI5: 1149 | AJ5: 468.26603 | AK5: -134.18312 | AL5: 2.0366925 | AM5: 20366.925 | AN5: Core | AO5: Occupancy | AP5: Established | AQ5: See structured fields (Thesis / Risks / Valuation / Trigger / Sources) for detail. | AR5: Zero-debt commercial real estate/exhibition-center operator; high-margin annuity-like business. | AS5: Current P/E, ROE, revenue growth not independently pulled - re-rating risk unassessed. | AT5: ROCE ~20-22%; operating margins ~60%; zero debt. | AU5: Pull current P/E/ROE/revenue growth from primary source. | AV5: Multiple sources this session, Jul-2026 (P/E/ROE/growth pending). | AW5: 58.540002 | AX5: 10 | AY5: 7.999078 | AZ5: 0.61 | BB5: 18.73249 | BD5: 100 | BE5: 9.0681547 | BF5: 100 | BH5: OK | BI5: Avoid | BM5: Extremely Overvalued
A6: 5 | B6: Persistent Systems | C6: PERSISTENT.NS | D6: IT | E6: Software | F6: 745143926784 | G6: Bench | H6: Pass | I6: 85 | J6: 39.911085 | K6: 90 | L6: 100 | M6: Low - thesis proven, monitor Nagarro integration | N6: Active | O6: IT services, US$1bn+ revenue, active M&A strategy | P6: 38.7 | Q6: 1.06 | R6: 1.04 | S6: 30.895357 | T6: 23.796307 | U6: 28.305862 | V6: 0.06 | W6: 2.1085144 | X6: 19.6 | Y6: 35.9 | AE6: Pending | AF6: Jul-2026 | AG6: Oct-2026 | AH6: 1580.9473 | AI6: 4683 | AJ6: 1976.1841 | AK6: -141.34897 | AL6: 3.9730174 | AM6: 39730.174 | AN6: Bench | AO6: Integration | AP6: Developing | AQ6: See structured fields (Thesis / Risks / Valuation / Trigger / Sources) for detail. | AR6: IT services + Nagarro-style digital engineering growth compounder; historically high ROCE. | AS6: Nagarro acquisition integration risk - do not score until integration clarity. | AT6: P/E 38.7x; 3yr ROE 25.4%; net debt-free; ROCE ~20% and rising (exact current figure pending); 10yr median sales growth 19.6%. | AU6: Nagarro integration clarity before scoring. | AV6: Verified 2026-07 (Tijori + others). | AW6: 118.7 | AX6: 18.146558 | AY6: 16.64856 | AZ6: 0.9 | BB6: 40.18113 | BD6: 100 | BE6: 6.0915646 | BF6: 100 | BH6: OK | BI6: Watch (Quality, Pricey) | BM6: Extremely Overvalued
A7: 6 | B7: RR Kabel | C7: RRKABEL.NS | D7: Consumer Discretionary | E7: Wires & Cables / FMEG | F7: 247531388928 | G7: Research | H7: Pass | I7: 58.5 | J7: 25.420734 | K7: 70 | L7: 100 | M7: Medium - confirm FY27 EPS growth guidance (~11%) | N7: None | O7: Cables & FMEG manufacturer; strong brand, electrification tailwind | P7: 46 | Q7: 0.74 | R7: 4.07 | T7: 19.119761 | U7: 25.476861 | V7: 0.08 | X7: 28 | Y7: 11 | AE7: Not started | AF7: Jul-2026 | AG7: Oct-2026 | AH7: 193.0625 | AI7: 2450 | AJ7: 241.32812 | AK7: -806.8566 | AL7: 2.5305505 | AM7: 25305.505 | AN7: Research | AO7: Watch | AP7: Early | AQ7: See structured fields (Thesis / Risks / Valuation / Trigger / Sources) for detail. | AR7: Wire & cable manufacturer; strong ROE/ROCE; zero long-term debt; no promoter pledge. | AS7: Richly valued relative to own history (downgraded Fair-from-Attractive Oct-2025); recent all-time-high raises valuation-discipline concern. | AT7: P/E ~46x (peer median ~50x); ROE 19.7%; ROCE 20.47% avg; PEG 0.74; net D/E 0.08; 5yr rev CAGR 15.1%, TTM growth 28%. | AU7: Valuation-discipline check before promotion (Business Confidence pending). | AV7: Verified 2026-07. | AW7: 43.589999 | AX7: 17.23768 | AY7: 5.5363185 | AZ7: 0.5 | BB7: 50.20647 | BD7: 100 | BE7: 13.091509 | BF7: 100 | BH7: OK | BI7: Avoid | BM7: Extremely Overvalued
A8: 7 | B8: Cummins India | C8: CUMMINSIND.NS | D8: Industrials | E8: Compressors/Diesel Engines | F8: 1524184252416 | G8: Research | H8: Pass | I8: 89.5 | J8: 44.557222 | K8: 80 | L8: 100 | M8: Low - monitor quarterly, high valuation | N8: None | O8: Diesel/alt-fuel engines & gensets; 51% Cummins Inc-backed, near debt-free, high-ROCE compounder | P8: 64.3 | Q8: 2.09 | R8: 2.05 | S8: 63.41099 | T8: 27.866731 | U8: 27.033079 | V8: 0.003 | W8: 0.97565117 | X8: 13 | Y8: 30.8 | AE8: Not started | AF8: Jul-2026 | AG8: Oct-2026 | AH8: 739.34857 | AI8: 5478 | AJ8: 924.18571 | AK8: -494.95618 | AL8: 4.4355251 | AM8: 44355.251 | AN8: Research | AO8: Watch | AP8: Early | AQ8: See structured fields (Thesis / Risks / Valuation / Trigger / Sources) for detail. | AR8: Diesel/alt-fuel engines & gensets; 51% Cummins Inc-backed; high-ROCE compounder. | AS8: Valuation re-rated hard (+95% 1yr) - entry discipline needed; PEG likely expensive given re-rating. | AT8: P/E 64.3x; ROCE 36.3%; ROE 28.2% (3yr 26.3%); near debt-free; 5yr sales growth 15%, TTM 13%; 5yr profit CAGR 22% (3yr 35%). | AU8: Entry-price discipline check before promotion; DC/BC not yet scored. | AV8: Verified 2026-07 (Screener). | AW8: 85.360009 | AX8: 10 | AY8: 10.826918 | AZ8: 1.21 | BB8: 64.41541 | BD8: 100 | BE8: 0.43078833 | BF8: 100 | BH8: OK | BI8: Watch (Quality, Pricey) | BM8: Extremely Overvalued
A9: 8 | B9: MTAR Technologies | C9: MTARTECH.NS | D9: Industrials | E9: Capital Goods - Precision Engineering (Defence/Space/Nuclear) | F9: 209980358656 | G9: Research | H9: Fail | I9: 44.5 | J9: 12.064365 | K9: 55 | L9: 100 | M9: Low - high valuation, weak ROE/ROCE vs threshold | N9: None | O9: Precision components: nuclear, space, defense, clean energy | P9: 190 | Q9: 2.49 | R9: 2.49 | S9: 156.94998 | T9: 11.43101 | U9: 13.395915 | V9: 0.3 | W9: 0.29615968 | X9: 29.6 | Y9: 76.2 | AE9: Not started | AF9: Jul-2026 | AG9: Jan-2027 | AH9: 353.86059 | AI9: 7034 | AJ9: 442.32574 | AK9: -1443.3196 | AL9: 1.2009679 | AM9: 12009.679 | AN9: Research | AO9: Watch | AP9: Early | AQ9: See structured fields (Thesis / Risks / Valuation / Trigger / Sources) for detail. | AR9: AI/defense/clean-energy narrative stock. | AS9: Client concentration (Bloom Energy exposure); valuation entirely narrative-driven, not supported by returns. | AT9: P/E ~190-258x (peer median ~34x); ROE only 7.26%; ROCE only 11.16% - both fail 20% threshold. | AU9: N/A - excluded outright, fails core profitability gate. | AV9: Verified 2026-07. | AW9: 30.830001 | AX9: 12.121 | AY9: 14.347251 | BB9: 221.42393 | BD9: 100 | BE9: 45.778137 | BF9: 100 | BH9: OK | BI9: Avoid | BM9: Extremely Overvalued
A10: 9 | B10: Aegis Logistics | C10: AEGISLOG.NS | D10: Energy | E10: Oil, Gas & Consumable Fuels (LPG/Liquid Logistics) | F10: 437135409152 | G10: Research | H10: Conflict | I10: 27.5 | J10: 7.2541443 | K10: 55 | L10: 100 | M10: Blocked - resolve ROCE conflict (24.93% vs 15.37%) before scoring | N10: None | O10: LPG/gas logistics & storage; infrastructure-like moat | P10: 39 | Q10: 1.18 | R10: 1.13 | S10: 38.387249 | T10: 10.224468 | U10: 11.363537 | V10: 0.1 | W10: 2.5099425 | X10: -0.1 | Y10: 33 | AE10: Not started | AF10: Jul-2026 | AG10: Sep-2026 | AH10: 435.74291 | AI10: 1325 | AJ10: 544.67864 | AK10: -128.64858 | AL10: 0.72212624 | AM10: 7221.2624 | AN10: Research (Blocked) | AO10: Watch | AP10: Early | AQ10: See structured fields (Thesis / Risks / Valuation / Trigger / Sources) for detail. | AR10: Logistics/energy-storage business with historically strong ROCE claims. | AS10: ROCE conflict unresolved (24.93% vs 15.37% across sources); revenue deceleration (-0.1% FY25 vs 5yr CAGR 28.2%); WACC 12.42% vs ROIC ~10.34% (one source implies value destruction). | AT10: ROE 20.43%; D/E 0.10 (above sector avg 0.03); P/E ~39x vs peer median ~23x. | AU10: Resolve ROCE conflict via primary source before scoring. | AV10: moneyworks4me, GuruFocus, other tracker (conflicting), Jul-2026. | AW10: 25.6 | AX10: 10.48835 | AY10: 21.276509 | AZ10: 0.97 | BB10: 48.648438 | BD10: 100 | BE10: 47.242587 | BF10: 100 | BH10: OK | BI10: Avoid | BM10: Extremely Overvalued
A11: 10 | B11: Neuland Laboratories | C11: NEULANDLAB.NS | D11: Healthcare | E11: Pharmaceuticals (API/CDMO) | F11: 242343772160 | G11: Research | H11: Conflict | I11: 73.5 | J11: 30.843404 | K11: 70 | L11: 100 | M11: Monitor - working capital / FCF trend | N11: None | O11: API/CDMO pharma manufacturer | P11: 64 | Q11: 1.73 | R11: 1.66 | S11: 50.665062 | T11: 19.418707 | U11: 21.74646 | V11: 0.4 | W11: -0.20627067 | X11: 37 | Y11: 37 | AE11: Not started | AF11: Jul-2026 | AG11: Oct-2026 | AH11: 904.68083 | AI11: 18944 | AJ11: 1130.851 | AK11: -1570.3349 | AL11: 3.0703596 | AM11: 30703.596 | AN11: Research | AO11: Watch | AP11: Early | AQ11: See structured fields (Thesis / Risks / Valuation / Trigger / Sources) for detail. | AR11: Pharma API/CDMO manufacturer; strong revenue growth and margins. | AS11: Negative FCF (-Rs.49.4cr) from working-capital build; Tijori flags WC dragging ROCE/ROE; promoter holding declining (-3.5% 3yr); company self-warns of 'irregular earnings patterns.' | AT11: P/E 64-95x (conflicting, unresolved); FY26 revenue +37%; Q4 EBITDA margin 40.5%. | AU11: Resolve P/E conflict via Screener; follow up on working-capital and promoter-selling trend. | AV11: Verified 2026-07 (conflicting across sources). | AW11: 283.49998 | AX11: 10 | AY11: 3.9771085 | AZ11: 0.18 | BB11: 66.62787 | BD11: 100 | BE11: 16.072369 | BF11: 100 | BH11: OK | BI11: Avoid | BM11: Extremely Overvalued
A12: 11 | B12: Elecon Engineering | C12: ELECON.NS | D12: Industrials | E12: Capital Goods - Industrial Gears/Material Handling | F12: 111762382848 | G12: Research | H12: Pass | I12: 44.5 | J12: 19.619076 | K12: 70 | L12: 100 | M12: Monitor - order-book/execution recovery after Q4 FY26 miss | N12: None | O12: Industrial gears/material handling equipment | P12: 35.19 | Q12: 2.01 | R12: 1.85 | S12: 26.282495 | T12: 14.795106 | U12: 16.713269 | V12: 0.12 | W12: 1.7261161 | X12: 17.5 | Y12: 17.5 | AE12: Not started | AF12: Jul-2026 | AG12: Oct-2026 | AH12: 156.73022 | AI12: 529 | AJ12: 195.91277 | AK12: -154.22028 | AL12: 1.9530146 | AM12: 19530.146 | AN12: Research | AO12: Watch | AP12: Early | AQ12: See structured fields (Thesis / Risks / Valuation / Trigger / Sources) for detail. | AR12: Industrial gear/power-transmission manufacturer; net cash position. | AS12: ROE below 20% IOS threshold; stock down -17.9% 52wk despite decent fundamentals. | AT12: P/E 35.2x; ROE 15.85%; ROIC 18.21%; D/E 0.12; net cash. | AU12: ROE needs to clear 20% threshold to qualify as core-quality candidate. | AV12: Verified 2026-07. | AW12: 15.180001 | AX12: 13.765009 | AY12: 12.90598 | AZ12: 0.39 | BB12: 32.809616 | BD12: 100 | BE12: 11.824376 | BF12: 100 | BH12: OK | BI12: Avoid | BM12: Extremely Overvalued
A13: 12 | B13: State Bank of India | C13: SBIN.NS | D13: Financial Services | E13: Public Sector Bank | F13: 9386615373824 | G13: Research | H13: Pass | I13: 23.333333 | J13: 0 | K13: 75 | L13: 60 | M13: Medium - standard quarterly monitoring (bank; ROCE/D-E not standard metrics) | N13: None | O13: Largest PSU bank by assets; ~22% deposit share, ~20% net advance share | ROCE/Debt-Equity shown are mechanically computed (Tijori/StockViz) - not economically standard metrics for a deposit-funded bank / borrowings-funded NBFC balance sheet; included per request, interpret with that context. | P13: 11.6 | Q13: 0.89 | R13: 0.8 | T13: 13.546739 | U13: 13.76 | V13: 1.33 | W13: 2.9231401 | X13: 5.2 | Y13: 13 | AE13: Not started | AF13: Jul-2026 | AG13: Oct-2026 | AH13: 728.23105 | AI13: 1040 | AJ13: 910.28882 | AK13: -11.711797 | AL13: 0.28207506 | AM13: 2820.7506 | AN13: Research | AO13: Watch | AP13: Early | AQ13: See structured fields (Thesis / Risks / Valuation / Trigger / Sources) for detail. | AR13: Largest PSU bank by assets; strong profit growth; cheap valuation. | AS13: Bank-specific yardstick applied (ROE>15%, not 20% threshold) - judgment call on cross-comparability; ROCE/D-E not meaningful for banks. | AT13: FY26 net profit Rs.80,032cr (+12.88% YoY); ROA 1.12%; ROE 18.57%; P/E ~11.6x; advances +16.87% YoY; deposits +11.03% YoY. | AU13: DC/BC not yet formally scored - first-pass research only. | AV13: Verified 2026-07 (GuruFocus). | AW13: 91.150003 | AX13: 10 | AY13: 9.9867122 | AZ13: 1.67 | BB13: 11.156336 | BD13: 60 | BE13: 100 | BF13: 100 | BH13: Missing EV/EBIT (EBIT <= 0) | BI13: Avoid | BM13: Overvalued
A14: 13 | B14: Titan Company | C14: TITAN.NS | D14: Consumer Discretionary | E14: Consumer Durables (Jewellery/Watches/Eyewear) | F14: 4068344332288 | G14: Research | H14: Conflict | I14: 72 | J14: 0 | K14: 50 | L14: 100 | M14: Blocked - resolve ROCE conflict (20-21% vs 37.37%) and D/E conflict (0 vs 1.56) | N14: None | O14: Jewellery/watches/eyewear lifestyle major, Tata Group | P14: 76.5 | Q14: 5.1 | R14: 4.64 | T14: 32.305929 | U14: 36.373267 | V14: 1.5 | X14: 17 | Y14: 15 | AE14: Not started | AF14: Jul-2026 | AG14: Sep-2026 | AH14: 959.34858 | AI14: 3550 | AJ14: 1199.1857 | AK14: -282.45952 | AL14: =IF(H14="Fail","Not Eligible (Failed Gate)",IF(J14="","Pending Score",IF(J14>=90,"10%",IF(J14>=80,"7.5%",IF(J14>=70,"5%","Watchlist only"))))) | AM14: =IFERROR(ROUND(VALUE(SUBSTITUTE(AL14,"%",""))/100*Dashboard!$B$11,0),"") | AN14: Research (Blocked) | AO14: Watch | AP14: Early | AQ14: See structured fields (Thesis / Risks / Valuation / Trigger / Sources) for detail. | AR14: Dominant jewelry/watches consumer franchise; strong headline ROE. | AS14: ROCE conflict (20-21% vs 37.37% across sources); D/E conflict (0 vs 1.56, likely Ind AS 116 lease treatment); Piotroski F-Score only 2/9 despite headline quality - notable red flag; P/E 76.5x vs industry median 21.6x, very rich. | AT14: ROE 28.7-37.7% (range, all periods strong). | AU14: Resolve ROCE and D/E conflicts before scoring. | AV14: Verified 2026-07 (multiple, conflicting). | AW14: 57.090001 | AX14: 25 | AY14: 21.00518 | AZ14: 0.33 | BB14: 80.33631 | BD14: 100 | BE14: 100 | BF14: 100 | BH14: OK | BI14: Avoid | BM14: Extremely Overvalued
A15: 14 | B15: Tech Mahindra | C15: TECHM.NS | D15: IT | E15: IT Services | F15: 1265662951424 | G15: Research | H15: Fail | I15: 62 | J15: 28.74671 | K15: 75 | L15: 100 | M15: Low - weak 5yr growth (8.5%), payout exceeds EPS | N15: None | O15: IT services subsidiary of Mahindra Group; telecom-heavy client mix | P15: 25.3 | Q15: 3.16 | R15: 2.66 | S15: 16.80694 | T15: 15.995279 | U15: 21.185826 | V15: 0.1 | W15: 4.4103958 | X15: 8.46 | Y15: 8 | AE15: Not started | AF15: Jul-2026 | AG15: Oct-2026 | AH15: 757.56325 | AI15: 1410 | AJ15: 946.95406 | AK15: -50.883772 | AL15: 2.8616406 | AM15: 28616.406 | AN15: Research | AO15: Watch | AP15: Early | AQ15: See structured fields (Thesis / Risks / Valuation / Trigger / Sources) for detail. | AR15: IT services subsidiary of Mahindra Group. | AS15: ROE well below 20% threshold; weak 5yr sales growth (8.46%); dividend payout 112% exceeds earnings. | AT15: P/E ~25.3x; 3yr ROE 13.3%. | AU15: N/A - excluded, no differentiated catalyst vs TCS. | AV15: Verified 2026-07 (Screener/GuruFocus). | AW15: 54.139997 | AX15: 10 | AY15: 17.49084 | AZ15: 3.52 | BB15: 26.39084 | BD15: 100 | BE15: 7.2686771 | BF15: 100 | BH15: OK | BI15: Avoid | BM15: Extremely Overvalued
A16: 15 | B16: Larsen & Toubro | C16: LT.NS | D16: Industrials | E16: EPC/Conglomerate | F16: 5354475749376 | G16: Research | H16: Conflict | I16: 27 | J16: 0.31861062 | K16: 55 | L16: 100 | M16: Blocked - need segment-level D/E excluding financial-services arm | N16: None | O16: Diversified EPC conglomerate: infra, hydrocarbon, defence, IT, financial services | P16: 33.8 | Q16: 2.82 | R16: 2.5 | S16: 24.557814 | T16: 12.513757 | U16: 13.66839 | V16: 1.12 | W16: 1.7948085 | X16: 12 | Y16: 12 | AE16: Not started | AF16: Jul-2026 | AG16: Sep-2026 | AH16: 1389.369 | AI16: 3693 | AJ16: 1736.7112 | AK16: -124.1075 | AL16: 0.031716641 | AM16: 317.16641 | AN16: Research (Blocked) | AO16: Watch | AP16: Early | AQ16: See structured fields (Thesis / Risks / Valuation / Trigger / Sources) for detail. | AR16: Diversified EPC conglomerate (infra, hydrocarbon, defence, IT, financial services). | AS16: ROE/ROCE both below 20% threshold; D/E elevated (1.12-1.41) but distorted by NBFC arm - needs segment-level resolution; net debt rising sharply. | AT16: P/E ~33.8x; ROE ~14.7-15%; ROCE ~17.85%. | AU16: Segment-level D/E excluding financial-services arm needed before scoring. | AV16: Verified 2026-07 (Tijori/Screener). | AW16: 116.96 | AX16: 12.020662 | AY16: 14.848762 | AZ16: 0.95 | BB16: 33.27719 | BD16: 100 | BE16: 97.639921 | BF16: 100 | BH16: OK | BI16: Avoid | BM16: Extremely Overvalued
A17: 16 | B17: Avalon Technologies | C17: AVALON.NS | D17: Industrials/IT Hardware | E17: Electronic Manufacturing Services (EMS) | F17: 108983336960 | G17: Research | H17: Fail | I17: 41 | J17: 14.451931 | K17: 70 | L17: 100 | M17: Low priority - structural Fail (ROE/ROCE below threshold), revisit only if fundamentals improve | N17: None | O17: EMS/electronics manufacturing, PCB to box-build | P17: 100 | Q17: 2.05 | R17: 1.99 | T17: 15.649885 | U17: 18.182954 | V17: 0.15 | X17: 18.4 | Y17: 48.7 | AE17: Not started | AF17: Jul-2026 | AG17: Jan-2027 | AH17: 85.337776 | AI17: 1800 | AJ17: 106.67222 | AK17: -1429.1704 | AL17: 1.4386423 | AM17: 14386.423 | AN17: Research (Low priority) | AO17: Watch | AP17: Early | AQ17: See structured fields (Thesis / Risks / Valuation / Trigger / Sources) for detail. | AR17: EMS (electronics manufacturing services) upcycle narrative stock. | AS17: ROE/ROCE fail 20% threshold by wide margin; P/E swung 76x-134x on pure re-rating (+118% 1yr) - narrative priced in well ahead of fundamentals. | AT17: ROE ~9-11% (3yr); ROCE avg 12.4%. | AU17: N/A - excluded, same pattern as MTAR. | AV17: Verified 2026-07. | AW17: 16.889999 | AX17: 10 | AY17: 6.3157027 | BB17: 96.57786 | BD17: 100 | BE17: 29.502775 | BF17: 100 | BH17: OK | BI17: Avoid | BM17: Extremely Overvalued
A18: 17 | B18: CG Power and Industrial Solutions | C18: CGPOWER.NS | D18: Industrials | E18: Capital Goods - Power/Electrical Equipment | F18: 1430238527488 | G18: Research | H18: Fail | I18: 40.5 | J18: 19.957276 | K18: 60 | L18: 100 | M18: Monitor - rich valuation vs order backlog growth | N18: None | O18: Electrical equipment, electrification/industrial capex play | P18: 121 | Q18: 4.03 | R18: 3.84 | S18: 98.994259 | T18: 14.71375 | U18: 17.067301 | V18: 0.1 | W18: -0.052638763 | X18: 25 | Y18: 30 | AE18: Not started | AF18: Jul-2026 | AG18: Oct-2026 | AH18: 33.107252 | AI18: 965 | AJ18: 41.384065 | AK18: -2094.3229 | AL18: 1.9866812 | AM18: 19866.812 | AN18: Research | AO18: Watch | AP18: Early | AQ18: See structured fields (Thesis / Risks / Valuation / Trigger / Sources) for detail. | AR18: Power equipment 'supercycle' narrative stock. | AS18: ROCE flagged as decreasing even without significant capex (unexplained); extreme valuation. | AT18: P/E ~121x (~200% premium to peer median ~40x); P/B ~18x vs peer median ~4.6x. | AU18: N/A - excluded, priced for flawless multi-year supercycle with no margin for error. | AV18: Session check, Jul-2026. | AW18: 7.7399998 | AX18: 16.259103 | AY18: 5.3467784 | AZ18: 0.14 | BB18: 117.32558 | BD18: 100 | BE18: 1.4455524 | BF18: 100 | BH18: OK | BI18: Avoid | BM18: Extremely Overvalued
A19: 18 | B19: Tejas Networks | C19: TEJASNET.NS | D19: Telecom | E19: Telecom Equipment | F19: 95095472128 | G19: Research | H19: Fail | I19: 0 | J19: 0 | K19: 70 | L19: 90 | M19: Monitor - loss-making, order lumpiness (BSNL contracts) | N19: None | O19: Wireline/wireless telecom equipment; Tata Group (Panatone Finvest) promoted | P19: N/A (loss-making) | T19: -31.010928 | U19: -29.36837 | V19: 0.9 | W19: -5.5116527 | X19: -88 | Y19: -88 | AE19: Not started | AF19: Jul-2026 | AG19: Oct-2026 | AI19: 602 | AK19: =IF(OR(NOT(ISNUMBER(AJ19)),AJ19<=0,AI19=""),"",ROUND((AJ19-AI19)/AJ19*100,1)) | AL19: =IF(H19="Fail","Not Eligible (Failed Gate)",IF(J19="","Pending Score",IF(J19>=90,"10%",IF(J19>=80,"7.5%",IF(J19>=70,"5%","Watchlist only"))))) | AM19: =IFERROR(ROUND(VALUE(SUBSTITUTE(AL19,"%",""))/100*Dashboard!$B$11,0),"") | AN19: Research (Weak) | AO19: Watch | AP19: Early | AQ19: See structured fields (Thesis / Risks / Valuation / Trigger / Sources) for detail. | AR19: Telecom equipment manufacturer, Tata-promoted. | AS19: FY26 net loss ~Rs.909cr; revenue collapse 88-90% YoY; negative ROE/ROCE; Debt/EBITDA ~7.94x while loss-making. | AT19: N/A - loss-making, no meaningful P/E. | AU19: N/A - excluded, capital destruction in progress. | AV19: Verified 2026-07. | AW19: =IFERROR(ROUND(AI19/P19,2),"N/A") | AX19: 10 | AY19: =IFERROR(IF(OR(T19="",T19=0,AW19="N/A",T19-AX19<3),"N/A",ROUND((1-(AX19/T19))*100/(Dashboard!$B$14-AX19),1)),"N/A") | AZ19: 0.42 | BD19: 50 | BE19: 100 | BF19: 50 | BH19: Negative FCF / DCF Invalid | Missing EV/EBIT (EBIT <= 0) | BI19: Avoid
A20: 19 | B20: ACME Solar Holdings | C20: ACMESOLAR.NS | D20: Utilities | E20: Renewable Power Generation | F20: 257972961280 | G20: Research | H20: Fail | I20: 35 | J20: 0 | K20: 65 | L20: 100 | M20: Monitor - ROE/ROCE below 20% threshold despite strong topline growth | N20: None | O20: Solar/wind/hybrid/FDRE + BESS developer-operator; PPA-based revenue | P20: 26 | Q20: 0.59 | R20: 0.57 | S20: 33.089849 | T20: 9.8596529 | U20: 5.1873073 | V20: 0.65 | W20: -9.3706583 | X20: 42.3 | Y20: 44 | AE20: Not started | AF20: Jul-2026 | AG20: Oct-2026 | AI20: 270 | AK20: =IF(OR(NOT(ISNUMBER(AJ20)),AJ20<=0,AI20=""),"",ROUND((AJ20-AI20)/AJ20*100,1)) | AL20: =IF(H20="Fail","Not Eligible (Failed Gate)",IF(J20="","Pending Score",IF(J20>=90,"10%",IF(J20>=80,"7.5%",IF(J20>=70,"5%","Watchlist only"))))) | AM20: =IFERROR(ROUND(VALUE(SUBSTITUTE(AL20,"%",""))/100*Dashboard!$B$11,0),"") | AN20: Research | AO20: Watch | AP20: Early | AQ20: See structured fields (Thesis / Risks / Valuation / Trigger / Sources) for detail. | AR20: Solar/wind/hybrid/FDRE + BESS developer; strong revenue growth. | AS20: ROE/ROCE well below 20% threshold; interest coverage thin (~1.15x); policy-dependent, capital-intensive profile (same as Premier Energies). | AT20: ROE ~7.6-10.6%; ROCE ~2.7-8.4%; D/E ~0.5-0.86; P/E ~26-90x (date-dependent). | AU20: N/A - exclude/monitor only, fails core profitability gate. | AV20: Verified 2026-07 (MarketsMojo/Screener). | AW20: 8.1499998 | AX20: 9.896106 | AY20: =IFERROR(IF(OR(T20="",T20=0,AW20="N/A",T20-AX20<3),"N/A",ROUND((1-(AX20/T20))*100/(Dashboard!$B$14-AX20),1)),"N/A") | AZ20: 0.05 | BB20: 44.815952 | BD20: 100 | BE20: 100 | BF20: 100 | BH20: Negative FCF / DCF Invalid | BI20: Avoid
A21: 20 | B21: Atul Auto | C21: ATULAUTO.NS | D21: Automobiles | E21: Three-Wheelers | F21: 13158268928 | G21: Research | H21: Fail | I21: 34 | J21: 11.985983 | K21: 70 | L21: 100 | M21: Low priority - ROE well below threshold, near-flat revenue CAGR | N21: None | O21: Three-wheeler (auto rickshaw) manufacturer, Gujarat-based, ~4% domestic market share | P21: 33 | Q21: 6.6 | R21: 5.08 | S21: 21.996143 | T21: 8.6222023 | U21: 11.963101 | V21: 0.2 | W21: 2.5266961 | X21: 2 | Y21: 5 | AE21: Not started | AF21: Jul-2026 | AG21: Jan-2027 | AH21: 204.7911 | AI21: 495 | AJ21: 255.98887 | AK21: -85.222897 | AL21: 1.1931653 | AM21: 11931.653 | AN21: Research (Low priority) | AO21: Watch | AP21: Early | AQ21: See structured fields (Thesis / Risks / Valuation / Trigger / Sources) for detail. | AR21: Three-wheeler manufacturer, Gujarat-based. | AS21: ROE only 5.72% (3yr); rich valuation on weak returns; revenue CAGR near-flat. | AT21: P/E ~26-44x. | AU21: N/A - excluded, narrow moat, weak capital efficiency. | AV21: Verified 2026-07 (Screener/MoneyWorks4Me). | AW21: 15.239999 | AX21: 10 | AY21: 16.79717 | BB21: 31.112206 | BD21: 100 | BE21: 29.494216 | BF21: 100 | BH21: OK | BI21: Avoid | BM21: Extremely Overvalued
A22: 21 | B22: Mahindra Holidays & Resorts India | C22: MHRIL.NS | D22: Consumer Discretionary | E22: Leisure & Hospitality | F22: 46791028736 | G22: Research | H22: Conflict | I22: 10 | J22: 0 | K22: 45 | L22: 100 | M22: Monitor - Altman Z-score 0.83 (weakest of peers), Q4 profit fell 43% on impairment | N22: None | O22: Vacation-ownership (Club Mahindra) + Holiday Club Resorts (Nordic/EU); Mahindra Group subsidiary | P22: 62.7 | Q22: 8.36 | R22: 6.97 | S22: 42.582362 | T22: 8.8702679 | U22: 2.2334238 | V22: 1.2 | W22: 1.2990752 | X22: 7.5 | Y22: -43 | AE22: Not started | AF22: Jul-2026 | AG22: Sep-2026 | AH22: 64.333199 | AI22: 230 | AJ22: 80.416498 | AK22: -188.51045 | AL22: =IF(H22="Fail","Not Eligible (Failed Gate)",IF(J22="","Pending Score",IF(J22>=90,"10%",IF(J22>=80,"7.5%",IF(J22>=70,"5%","Watchlist only"))))) | AM22: =IFERROR(ROUND(VALUE(SUBSTITUTE(AL22,"%",""))/100*Dashboard!$B$11,0),"") | AN22: Research (Weak) | AO22: Watch | AP22: Early | AQ22: See structured fields (Thesis / Risks / Valuation / Trigger / Sources) for detail. | AR22: Vacation-ownership (Club Mahindra) + Holiday Club Resorts (Nordic/EU). | AS22: Q4 FY26 profit -43.1% YoY (Mauritius impairment + soft EU); ROCE decreasing; Altman Z-score only 0.83 (weakest of 8 peers) - financial-stability red flag. | AT22: P/E ~62.7x (98% premium to peer median). | AU22: Resolve Altman Z / balance-sheet-strength concern before any scoring. | AV22: Verified 2026-07 (Screener/Tijori/Groww). | AW22: 3.4500001 | AX22: 8.972 | AY22: 23.30913 | BB22: 67.249275 | BD22: 100 | BE22: 100 | BF22: 100 | BH22: OK | BI22: Avoid | BM22: Extremely Overvalued
A23: 22 | B23: Power Finance Corporation | C23: PFC.NS | D23: Financial Services | E23: Infrastructure Finance NBFC | F23: 1331921027072 | G23: Research | H23: Pass | I23: 33.333333 | J23: 0 | K23: 50 | L23: 60 | M23: Blocked - PFC-REC merger integration pending, do not score standalone metrics | N23: PFC-REC merger (board-approved 28-Jun-2026, 88:100 swap) | O23: Maharatna PSU infra-finance NBFC lending to power-sector utilities; PFC-REC merger in progress | ROCE/Debt-Equity shown are mechanically computed (Tijori/StockViz) - not economically standard metrics for a deposit-funded bank / borrowings-funded NBFC balance sheet; included per request, interpret with that context. | P23: 6.5 | Q23: 0.43 | R23: 0.39 | T23: 14.933578 | U23: 10.26 | V23: 8.25 | W23: -0.40975016 | X23: 10 | Y23: 15 | AE23: Not started | AF23: Jul-2026 | AG23: Sep-2026 | AH23: 233.48822 | AI23: 423 | AJ23: 291.86027 | AK23: -38.285352 | AL23: 0.057225105 | AM23: 572.25105 | AN23: Research (Blocked - Merger) | AO23: Corporate action | AP23: Early | AQ23: See structured fields (Thesis / Risks / Valuation / Trigger / Sources) for detail. | AR23: Maharatna PSU infra-finance NBFC lending to power-sector utilities. | AS23: PFC-REC merger (approved 28-Jun-2026) creates integration/dilution uncertainty; State DISCOM loan-book concentration. | AT23: ROE ~19.49%; P/E ~5.6-7.3x (deep discount to peer avg ~17-18x); dividend yield ~5%. | AU23: Merger integration must clear before scoring stabilizes. | AV23: Verified 2026-07 (MarketsMojo/GuruFocus). | AW23: 78.5 | AX23: 16.125162 | AY23: 3.7179652 | AZ23: 3.82 | BB23: 5.1414013 | BD23: 60 | BE23: 100 | BF23: 100 | BH23: Missing EV/EBIT (EBIT <= 0) | BI23: Avoid | BM23: Overvalued
A24: 23 | B24: ITC | C24: ITC.NS | D24: Consumer Staples | E24: Diversified FMCG | F24: 3516395159552 | G24: Research | H24: Pass | I24: 77 | J24: 46.970317 | K24: 80 | L24: 100 | M24: Monitor - Q4 FY26 profit fell 73% YoY on base effect, use FY figure for trend | N24: None | O24: Dominant cigarettes + FMCG (25+ brands) + paperboards/agri conglomerate; hotels demerged Jan-2025 | P24: 17.6 | Q24: 3.52 | R24: 2.71 | S24: 13.821202 | T24: 28.391125 | U24: 33.195647 | V24: 0.03 | W24: 4.6023767 | X24: 9.87 | Y24: 5 | AE24: Not started | AF24: Jul-2026 | AG24: Oct-2026 | AH24: 163.97566 | AI24: 289 | AJ24: 204.96958 | AK24: -36.922757 | AL24: 4.6757408 | AM24: 46757.408 | AN24: Research | AO24: Watch | AP24: Mature | AQ24: See structured fields (Thesis / Risks / Valuation / Trigger / Sources) for detail. | AR24: Dominant cigarettes + FMCG + paperboards/agri conglomerate. | AS24: 5yr sales growth only 9.87% (poor) - cigarette-volume dependency, FMCG-Others scaling slowly; ongoing restructuring (Sresta/Wimco amalgamation) to watch. | AT24: 3yr ROE 35.2%; P/E ~17.6-19x; dividend yield ~5%; near debt-free; payout 74.5%. | AU24: Growth-catalyst check needed before promotion. | AV24: Verified 2026-07 (Screener). | AW24: 16.52 | AX24: 10 | AY24: 12.40736 | AZ24: 5.54 | BB24: 16.988499 | BD24: 100 | BE24: 3.2925217 | BF24: 100 | BH24: OK | BI24: Watch (Quality, Pricey) | BM24: Overvalued
A25: 24 | B25: Eicher Motors | C25: EICHERMOT.NS | D25: Automobiles | E25: Two-Wheelers/Commercial Vehicles | F25: 2036360019968 | G25: Research | H25: Pass | I25: 72 | J25: 35.262865 | K25: 80 | L25: 100 | M25: Monitor - rich valuation, EV portfolio gap flagged by analysts | N25: None | O25: Royal Enfield (global leader, mid-weight motorcycles) + VECV JV with AB Volvo (trucks/buses) | P25: 38 | Q25: 2.11 | R25: 1.95 | S25: 41.239238 | T25: 21.972897 | U25: 18.219516 | V25: 0.05 | W25: 1.7309019 | X25: 15.6 | Y25: 18 | AE25: Not started | AF25: Jul-2026 | AG25: Oct-2026 | AH25: 2110.3523 | AI25: 7454 | AJ25: 2637.9404 | AK25: -181.22319 | AL25: 3.5103024 | AM25: 35103.024 | AN25: Research | AO25: Watch | AP25: Early | AQ25: See structured fields (Thesis / Risks / Valuation / Trigger / Sources) for detail. | AR25: Royal Enfield (global mid-weight motorcycle leader) + VECV JV with AB Volvo. | AS25: Valuation stretched (P/E ~38-41x, 'somewhat overvalued' per MoneyWorks4Me); P/B ~8-9.6x. | AT25: Current ROE ~24%; near debt-free; revenue CAGR ~15.6% (vs ~13.4% industry median). | AU25: Same valuation-discipline check as RR Kabel before promotion. | AV25: Verified 2026-07 (Screener/MoneyWorks4Me/Wisesheets). | AW25: 200.46002 | AX25: 15.484006 | AY25: 13.159435 | AZ25: 1.09 | BB25: 37.00738 | BD25: 100 | BE25: 2.0475973 | BF25: 100 | BH25: OK | BI25: Hold | BM25: Extremely Overvalued
A26: 25 | B26: CreditAccess Grameen | C26: CREDITACC.NS | D26: Financial Services | E26: Microfinance NBFC | F26: 246173237248 | G26: Research | H26: Conflict | I26: 35 | J26: 0 | K26: 55 | L26: 100 | M26: Active - confirm ROE/ROA recovery holds 2 more quarters vs FY27 guidance (16-20%) | N26: None | O26: India's largest MFI (Grameen Koota); diversifying into retail/individual/two-wheeler lending | ROCE/Debt-Equity shown are mechanically computed (Tijori/StockViz) - not economically standard metrics for a deposit-funded bank / borrowings-funded NBFC balance sheet; included per request, interpret with that context. | P26: 41.9 | Q26: 0.07 | R26: 0.07 | T26: 9.9160318 | U26: 14.811537 | V26: 2.96 | X26: 14 | Y26: 619 | AE26: Not started | AF26: Jul-2026 | AG26: Sep-2026 | AI26: 1460 | AK26: =IF(OR(NOT(ISNUMBER(AJ26)),AJ26<=0,AI26=""),"",ROUND((AJ26-AI26)/AJ26*100,1)) | AL26: =IF(H26="Fail","Not Eligible (Failed Gate)",IF(J26="","Pending Score",IF(J26>=90,"10%",IF(J26>=80,"7.5%",IF(J26>=70,"5%","Watchlist only"))))) | AM26: =IFERROR(ROUND(VALUE(SUBSTITUTE(AL26,"%",""))/100*Dashboard!$B$11,0),"") | AN26: Research (Recovery watch) | AO26: Watch | AP26: Early | AQ26: See structured fields (Thesis / Risks / Valuation / Trigger / Sources) for detail. | AR26: India's largest MFI (Grameen Koota); diversifying into retail/individual/two-wheeler lending. | AS26: Trailing 3yr ROE only 13.8% (below threshold) after FY26 MFI-sector stress (Karnataka delinquencies). | AT26: FY26 full-year ROA 2.7%/ROE 10.7%; Q4 FY26 recovered to ROA 4.4%/ROE 17.8%; GNPA improved to 3.17%; P/E ~41.9x. FY27 guidance ROE 16-20%. | AU26: Needs 1-2 more quarters of recovery confirmation vs guidance. | AV26: Verified 2026-07 (Screener/company guidance/MOFSL). | AW26: 48.420001 | AX26: 10.510001 | AY26: =IFERROR(IF(OR(T26="",T26=0,AW26="N/A",T26-AX26<3),"N/A",ROUND((1-(AX26/T26))*100/(Dashboard!$B$14-AX26),1)),"N/A") | BB26: 31.736885 | BD26: 100 | BE26: 100 | BF26: 100 | BH26: Negative FCF / DCF Invalid | BI26: Avoid
A27: 26 | B27: Punjab National Bank | C27: PNB.NS | D27: Financial Services | E27: Public Sector Bank | F27: 1160212512768 | G27: Research | H27: Fail | I27: 16.666667 | J27: 12.037534 | K27: 70 | L27: 60 | M27: Low - PSU bank, improving but sub-scale vs SBI | N27: None | O27: India's 2nd-largest PSU bank; post-NPA-cycle turnaround story, govt-owned (Promoter 70.1%) | ROCE/Debt-Equity shown are mechanically computed (Tijori/StockViz) - not economically standard metrics for a deposit-funded bank / borrowings-funded NBFC balance sheet; included per request, interpret with that context. | P27: 7.3 | Q27: 0.74 | R27: 0.65 | T27: 12.207936 | U27: 15.27 | V27: 0.66 | W27: 61.792755 | X27: 9.8 | Y27: -46 | AE27: Not started | AF27: Jul-2026 | AG27: Oct-2026 | AH27: 260.39497 | AI27: 106 | AJ27: 325.49371 | AK27: 68.985575 | AL27: 0.71897821 | AM27: 7189.7821 | AN27: Research | AO27: Watch | AP27: Early | AQ27: See structured fields (Thesis / Risks / Valuation / Trigger / Sources) for detail. | AR27: India's 2nd-largest PSU bank; post-NPA-cycle turnaround story. | AS27: ROE below SBI's and below 20% (non-bank) threshold; 5yr sales growth poor (9.8%). | AT27: ROE ~14.9%; ROA ~0.9-1.1%; P/E ~7.3-8x (cheap). | AU27: N/A - excluded vs SBI as better-quality PSU-bank exposure. | AV27: Verified 2026-07 (Screener/GuruFocus/Univest). | AW27: 16 | AX27: 10.63082 | AY27: 20.343357 | AZ27: 2.89 | BB27: 6.309375 | BD27: 60 | BE27: 57.259543 | BF27: 100 | BH27: Missing EV/EBIT (EBIT <= 0) | BI27: Avoid | BM27: Undervalued
A28: 27 | B28: Coforge | C28: COFORGE.NS | D28: Information Technology | E28: IT Services & Consulting | F28: 640086638592 | G28: Deferred | H28: Conflict | I28: 79 | J28: 36.530339 | K28: 93 | L28: 100 | M28: High - resolvable via post-Encora quarterly filings | N28: Cigniti Technologies amalgamation (completed) | O28: IT services, post-Encora acquisition integration phase | P28: 37 | Q28: 0.4 | R28: 0.4 | S28: 26.97647 | T28: 16.070285 | U28: 21.089012 | V28: 0.7 | W28: 1.6448786 | X28: 35.9 | Y28: 91.6 | AE28: Not started | AF28: Jul-2026 | AG28: Oct-2026 | AH28: 377.53759 | AI28: 1464 | AJ28: 471.92198 | AK28: -206.38539 | AL28: 3.6364753 | AM28: 36364.753 | AN28: Deferred | AO28: Watch | AP28: Early | AQ28: See structured fields (Thesis / Risks / Valuation / Trigger / Sources) for detail. | AR28: IT services + Encora acquisition-led growth. | AS28: Thesis Health Score revised down 83->71/100; Encora funded via ~20% equity dilution (Rs.17,032cr QIP) plus debt roughly tripling; PE-sponsor (Advent/Warburg) stake-sale overhang; same IT theme as TCS - cannot hold both under one-theme-per-core-slot rule. | AT28: P/E ~36-38x vs TCS ~18.6x (~2x premium). | AU28: 2 consecutive quarters of post-Encora integration proof, debt reduction, EPS accretion validated. | AV28: Session review (multiple). | AW28: 43.819998 | AX28: 10 | AY28: 10.769557 | AZ28: 1.06 | BB28: 32.99635 | BD28: 100 | BE28: 7.518129 | BF28: 100 | BH28: OK | BI28: Watch (Quality, Pricey) | BM28: Extremely Overvalued
A29: 28 | B29: Premier Energies | C29: PREMIERENE.NS | D29: Utilities/Industrials | E29: Solar Cell & Module Manufacturing | F29: 471108452352 | G29: Deferred | H29: Conflict | I29: 72.5 | J29: 10.14607 | K29: 80 | L29: 100 | M29: Medium - structural (policy) + resolvable (FCF checkpoint) mixed gap | N29: None | O29: Solar cell/module manufacturing, capacity expansion phase | P29: 30.8 | Q29: 0.51 | R29: 0.5 | S29: 25.642084 | T29: 35.026478 | U29: 25.181249 | V29: 0.86 | W29: -3.5188272 | X29: 44 | Y29: 60 | AE29: Not started | AF29: Jul-2026 | AG29: Oct-2026 | AI29: 1065 | AK29: =IF(OR(NOT(ISNUMBER(AJ29)),AJ29<=0,AI29=""),"",ROUND((AJ29-AI29)/AJ29*100,1)) | AL29: 1.0100079 | AM29: 10100.079 | AN29: Deferred (Policy-dependent) | AO29: Watch | AP29: Early | AQ29: See structured fields (Thesis / Risks / Valuation / Trigger / Sources) for detail. | AR29: Solar module/cell manufacturer; high ROE; policy-tailwind (ALMM/PLI) beneficiary. | AS29: D/E ~0.86 fails <0.3 threshold; FCF currently negative (~-Rs.17.4bn) from heavy capex; policy-dependent (structural, permanent risk tag). | AT29: PEG ~1.06 (passes); ROE ~42% (strong). | AU29: FCF-to-positive checkpoint, review quarterly. | AV29: Session review. | AW29: 33.599997 | AX29: 10 | AY29: =IFERROR(IF(OR(T29="",T29=0,AW29="N/A",T29-AX29<3),"N/A",ROUND((1-(AX29/T29))*100/(Dashboard!$B$14-AX29),1)),"N/A") | AZ29: 0.15 | BB29: 31.068455 | BD29: 100 | BE29: 86.005421 | BF29: 100 | BH29: Negative FCF / DCF Invalid | BI29: Avoid
A30: 29 | B30: Star Health and Allied Insurance Company | C30: STARHEALTH.NS | D30: Financial Services | E30: General/Health Insurance | F30: 343745331200 | G30: Deferred | H30: Pass | I30: 56.666667 | J30: 26.969425 | K30: 92 | L30: 60 | M30: High - resolvable via next 1-2 quarters underwriting data | N30: None | O30: Standalone health insurer, retail-focused | P30: 45 | Q30: 1.7 | R30: 1.61 | T30: 7.3760267 | U30: 11.65 | V30: 0.05 | W30: 5.3750829 | X30: 26.4 | Y30: -30 | AE30: Not started | AF30: Jul-2026 | AG30: Sep-2026 | AH30: 313.1432 | AI30: 587 | AJ30: 391.429 | AK30: -49.248013 | AL30: 1.6108306 | AM30: 16108.306 | AN30: Deferred (Weak ROE) | AO30: Watch | AP30: Early | AQ30: See structured fields (Thesis / Risks / Valuation / Trigger / Sources) for detail. | AR30: Health insurer; underwriting profitability recovering. | AS30: Retail claim settlement ratio only 92% (not 99%, which was actually renewal ratio - correction needed); solvency ratio (214%) not independently verified; durability vs medical inflation (12-13% expected 2026) and pending commission regulation untested. | AT30: Combined ratio 98.9% (Q3 FY26, improved from 102.1% YoY); renewal ratio 99%; loss/incurred claim ratio improved 71.8%->68.8%. | AU30: Awaiting 1-2 more quarters before candidate-pool promotion. | AV30: Session review; Business Confidence = Moderate. | AW30: 9.4899994 | AX30: 10 | AY30: 41.24647 | BB30: 61.55954 | BD30: 60 | BE30: 6.2241598 | BF30: 100 | BH30: Missing EV/EBIT (EBIT <= 0) | BI30: Avoid | BM30: Overvalued
A31: 30 | B31: Vikram Solar | C31: VIKRAMSOLR.NS | D31: Industrials | E31: Solar PV Module Manufacturing | F31: 66560876544 | G31: Deferred | H31: Conflict | I31: 55 | J31: 21.89948 | K31: 40 | L31: 100 | M31: Blocked - understand NCLAT set-aside (29-Jun-2026) and reconcile D/E before further work | N31: NCLAT set aside NCLT Kolkata insolvency admission (29-Jun-2026) | O31: Solar PV module manufacturer + EPC/O&M; large order book (10.3GW, 2x FY25 capacity) | P31: 16.5 | Q31: 0.07 | R31: 0.07 | S31: 9.6280803 | T31: 14.850273 | U31: 20.117923 | V31: 1.81 | W31: -1.2737691 | X31: 28.5 | Y31: 236 | AE31: Not started | AF31: Jul-2026 | AG31: Aug-2026 | AH31: 44.729796 | AI31: 189 | AJ31: 55.912244 | AK31: -228.53269 | AL31: 2.1800213 | AM31: 21800.213 | AN31: Deferred (Blocked - legal) | AO31: Watch | AP31: Early | AQ31: See structured fields (Thesis / Risks / Valuation / Trigger / Sources) for detail. | AR31: Solar PV module manufacturer + EPC/O&M; large order book (10.3GW). | AS31: MAJOR: NCLT insolvency case (set aside by NCLAT 29-Jun-2026, root cause unverified); D/E conflict (1.81x vs implied lower post-paydown); previously flagged as 'story over evidence' lapse. | AT31: P/E ~16.5x (cheap, 42% discount to peer median); ROE improved to 19.67% (2024) from 4.05% (2023); revenue CAGR 17-28.5%; Altman Z-score 3.87. | AU31: Insolvency matter fully understood AND D/E reconciled to primary filing before promotion out of Conflict. | AV31: Verified 2026-07 (Screener/Tijori/ValueResearch/wwipl). | AW31: 13.589999 | AX31: 10 | AY31: 4.1142196 | BB31: 13.516557 | BD31: 100 | BE31: 20.365526 | BF31: 100 | BH31: OK | BI31: Avoid | BM31: Extremely Overvalued
A32: 31 | B32: SANDUMA | C32: SANDUMA.NS | D32: Materials | E32: Mining - Manganese & Iron Ore | F32: 97177214976 | G32: ML Screen | H32: Fail | I32: 85 | J32: 75.449465 | K32: 70 | L32: 100 | M32: Monitor - cyclical commodity, capacity expansion approved | N32: None | O32: Metals & Mining (iron ore) | P32: 15.6 | Q32: 0.31 | R32: 0.3 | S32: 10.70772 | T32: 20.082024 | U32: 25.161829 | V32: 0.5 | W32: 9.2480465 | X32: 89 | Y32: 50 | AE32: Not started | AF32: Jul-2026 | AG32: Oct-2026 | AH32: 221.61364 | AI32: 220 | AJ32: 277.01705 | AK32: 27.834767 | AL32: 7.5107465 | AM32: 75107.465 | AN32: ML Screen | AO32: Watch | AP32: Early | AQ32: See structured fields (Thesis / Risks / Valuation / Trigger / Sources) for detail. | AR32: N/A - excluded on cyclicality principle. | AS32: ML Alpha screen only, unverified against primary source; commodity-price-driven earnings. | AT32: Not independently verified. | AU32: N/A - excluded, doesn't fit quality-compounder bucket regardless of screen score. | AV32: ML Alpha screen only (unverified). | AW32: 13.5 | AX32: 10 | AY32: 20.519782 | AZ32: 0.2 | BB32: 14.808148 | BD32: 100 | BE32: 30.563431 | BF32: 100 | BH32: OK | BI32: Buy | BM32: Undervalued
A33: 32 | B33: NMDC | C33: NMDC.NS | D33: Materials | E33: Iron Ore Mining (PSU) | F33: 736226770944 | G33: ML Screen | H33: Fail | I33: 79.5 | J33: 48.885755 | K33: 75 | L33: 100 | M33: Monitor - PSU miner, iron ore price sensitive | N33: None | O33: Iron ore mining, PSU | P33: 10.2 | Q33: 0.29 | R33: 0.28 | S33: 9.0973409 | T33: 21.864179 | U33: 24.251045 | V33: 0.13 | W33: 2.2848574 | X33: 60.7 | Y33: 35 | AE33: Not started | AF33: Jul-2026 | AG33: Oct-2026 | AH33: 53.908398 | AI33: 88 | AJ33: 67.385498 | AK33: -24.270062 | AL33: 4.8664164 | AM33: 48664.164 | AN33: ML Screen | AO33: Watch | AP33: Early | AQ33: See structured fields (Thesis / Risks / Valuation / Trigger / Sources) for detail. | AR33: N/A - excluded on cyclicality principle. | AS33: Cyclical commodity business, earnings swing with iron ore prices. | AT33: P/E 10.2; ROE 23.4% (ML Alpha screen, statistically attractive but not IOS-fit). | AU33: N/A - excluded early in session. | AV33: ML Alpha screen (unverified vs primary). | AW33: 8.4700003 | AX33: 13.709408 | AY33: 7.9557849 | AZ33: 4.15 | BB33: 9.886659 | BD33: 100 | BE33: 18.801576 | BF33: 100 | BH33: OK | BI33: Watch (Quality, Pricey) | BM33: Overvalued
A34: 33 | B34: Ashapura Minechem | C34: ASHAPURMIN.NS | D34: Materials | E34: Mining & Mineral Processing (Bauxite/Bentonite) | F34: 59928293376 | G34: ML Screen | H34: Fail | I34: 40 | J34: 2.4451159 | K34: 65 | L34: 100 | M34: Monitor - FY26 revenue nearly doubled, net debt declining | N34: None | O34: Metals & Mining (bentonite/bauxite) | P34: 15.6 | Q34: 0.39 | R34: 0.38 | S34: 16.8577 | T34: 24.404954 | U34: 15.099023 | V34: 0.69 | W34: 2.5788648 | X34: 98 | Y34: 40 | AE34: Not started | AF34: Jul-2026 | AG34: Oct-2026 | AH34: 316.92438 | AI34: 670 | AJ34: 396.15547 | AK34: -58.359544 | AL34: 0.24340326 | AM34: 2434.0326 | AN34: ML Screen | AO34: Watch | AP34: Early | AQ34: See structured fields (Thesis / Risks / Valuation / Trigger / Sources) for detail. | AR34: N/A - excluded on cyclicality principle. | AS34: ML Alpha screen only, unverified against primary source. | AT34: Not independently verified. | AU34: N/A - excluded, same cyclicality principle as NMDC/SANDUMA. | AV34: ML Alpha screen only (unverified). | AW34: 42.05 | AX34: 10 | AY34: 9.4210576 | AZ34: 0.16 | BB34: 14.919144 | BD34: 100 | BE34: 87.77442 | BF34: 100 | BH34: OK | BI34: Avoid | BM34: Extremely Overvalued
A35: 34 | B35: BLS International Services | C35: BLS.NS | D35: Consumer Discretionary | E35: Visa/Consular/IT-enabled Government Services | F35: 99876446208 | G35: ML Screen | H35: Conflict | I35: 89.5 | J35: 82.761066 | K35: 75 | L35: 100 | M35: Active - confirm FY27 govt contract renewal terms | N35: None | O35: Visa/govt-outsourcing services | P35: 15.3 | Q35: 0.44 | R35: 0.42 | S35: 14.125659 | T35: 24.668842 | U35: 23.078704 | V35: 0.1 | W35: 7.4758296 | X35: 36.7 | Y35: 35.1 | AE35: Not started | AF35: Jul-2026 | AG35: Oct-2026 | AH35: 214.28331 | AI35: 262 | AJ35: 267.85413 | AK35: 9.390982 | AL35: 8.2385923 | AM35: 82385.923 | AN35: ML Screen (Active) | AO35: Watch | AP35: Early | AQ35: See structured fields (Thesis / Risks / Valuation / Trigger / Sources) for detail. | AR35: Visa/consular outsourcing services provider. | AS35: ROCE inconsistent across sources (28% vs 64%, large spread); management self-disclosed government-contract renewal uncertainty on Q4 call; FY27 growth guidance (20-25%) is a deceleration from FY26 actual; some trackers show P/E >1000x (likely low-base-year distortion). | AT35: ML screen: P/E 15.3, ROE 32.7%, F-Score 8 (looks clean on screen). | AU35: FY27 contract renewals confirmed and valuation reset before promotion. | AV35: ML screen + deeper session research (conflicting). | AW35: 16.65 | AX35: 10 | AY35: 16.087335 | AZ35: 1.21 | BB35: 14.576577 | BD35: 100 | BE35: 15.467927 | BF35: 100 | BH35: OK | BI35: Strong Buy | BM35: Fair Value
A36: 35 | B36: eClerx Services | C36: ECLERX.NS | D36: Information Technology | E36: Outsourced Services/BPO/Analytics | F36: 135948935168 | G36: ML Screen | H36: Conflict | I36: 89.5 | J36: 56.157595 | K36: 70 | L36: 100 | M36: Monitor - ROCE-decline explanation, profit-quality check needed | N36: None | O36: BPM/analytics, IT-adjacent services | P36: 19.4 | Q36: 0.79 | R36: 0.75 | S36: 15.165256 | T36: 27.540796 | U36: 29.297859 | V36: 0.13 | W36: 5.6777716 | X36: 23 | Y36: 24.5 | AE36: Not started | AF36: Jul-2026 | AG36: Oct-2026 | AH36: 936.70035 | AI36: 1400 | AJ36: 1170.8754 | AK36: -26.170552 | AL36: 5.5903041 | AM36: 55903.041 | AN36: ML Screen | AO36: Watch | AP36: Early | AQ36: See structured fields (Thesis / Risks / Valuation / Trigger / Sources) for detail. | AR36: KPO/analytics services provider. | AS36: Tijori flags ROCE decreasing despite no significant capex (unexplained); lower depreciation rate inflating net profit; possible aggressive revenue recognition (receivables growing faster than sales, poor OCF conversion); rating fell Strong Buy(Jan-2026)->Sell(Jun-2026); theme overlaps with TCS (IT). | AT36: ML screen: P/E 19.4, ROE 29%, F-Score 8. | AU36: Resolve ROCE-decline explanation; document IT-theme exception before promotion. | AV36: ML screen + Tijori (session review). | AW36: 74.47 | AX36: 10 | AY36: 15.72278 | AZ36: 0.03 | BB36: 19.837519 | BD36: 100 | BE36: 15.012347 | BF36: 100 | BH36: OK | BI36: Watch | BM36: Overvalued
A37: 36 | B37: Sharda Cropchem | C37: SHARDACROP.NS | D37: Basic Materials | E37: Agrochemicals (registration/export model) | F37: 79754919936 | G37: Data Hold | H37: Fail | I37: 58 | J37: 37.323157 | K37: 35 | L37: 100 | M37: Blocked - reconcile FY26 revenue/PAT vs BSE filing and ROE-basis conflict before proceeding | N37: None | O37: Asset-light agrochemical registration/distribution platform, not a manufacturer | P37: 12 | Q37: 0.21 | R37: 0.21 | S37: 10.847496 | T37: 21.703961 | U37: 21.066641 | V37: 0.1 | W37: 2.042241 | X37: 13 | Y37: 57 | AE37: Not started | AF37: Jul-2026 | AG37: Before further work | AH37: 521.34273 | AI37: 885 | AJ37: 651.67841 | AK37: -35.64973 | AL37: 3.7153977 | AM37: 37153.977 | AN37: Data Hold | AO37: FY26 Reconciliation | AP37: Unresolved | AQ37: See structured fields (Thesis / Risks / Valuation / Trigger / Sources) for detail. | AR37: Agrochemical (generic crop-protection) exporter. | AS37: TWO unresolved conflicts: (1) 3yr avg ROE 13.6% (Screener) vs 24.2% (ML screen), explainable by down-cycle-vs-recovery-year averaging; (2) FY26 revenue/profit figures disagree materially across sources (Rs.5,268cr/Rs.681cr vs Rs.4,379cr/Rs.304cr for same fiscal year, ~20-120% apart) - UNRESOLVED. Europe ~45% revenue concentration; 166-day receivables; pesticide-registration regulatory risk. | AT37: Not usable until conflicts resolved. | AU37: Confirm FY26 revenue/profit directly against Sharda's BSE filing before any scoring. | AV37: Screener vs ML screen (conflicting); Data Confidence gate not passed. | AW37: 75.490002 | AX37: 20.316037 | AY37: 8.6326455 | AZ37: 1.97 | BB37: 11.71016 | BD37: 100 | BE37: 0 | BF37: 100 | BH37: OK | BI37: Hold | BM37: Overvalued

Sheet Financial Data
A1: Company | B1: Quarter | C1: Revenue | D1: Revenue Growth % | E1: EBITDA | F1: EBITDA Margin % | G1: Net Profit | H1: EPS | I1: EPS Growth % | J1: Operating Cash Flow | K1: Free Cash Flow | L1: FCF Yield % | M1: ROE % | N1: ROCE % | O1: ROA % | P1: Debt/Equity | Q1: Interest Coverage | R1: Current Ratio | S1: P/E | T1: PEG | U1: PEGY | V1: EV/EBIT | W1: P/B | X1: Dividend Yield % | Y1: Notes
A2: Lupin | B2: FY26 | D2: 23 | M2: 29.1 | N2: 28.4 | X2: Verified 2026-07: FY26 revenue growth 23%, ROCE 28.4%, EBITDA margin +~590bps. Q4 gross margin 75% vs 61.7% YoY - specialty/complex-generics mix shift, not one-off pricing. Net cash ~₹4,600cr. Source: company FY26 results coverage, this session. | Y2: Populate from annual report
A3: Cummins India | B3: FY26 TTM | C3: 11602 | D3: 13 | G3: 2242 | M3: 28.2 | N3: 36.3 | P3: 0.003 | S3: 64.3 | X3: 0.95 | Y3: Source: Screener.in consolidated, Jul-2026. TTM figures; FY26 annual not yet fully reported at fetch time.
A4: State Bank of India | B4: FY26 | G4: 80032 | M4: 18.57 | O4: 1.12 | S4: 11.6 | Y4: Source: SBI FY26 results coverage (Groww), GuruFocus, Jul-2026. Net profit +12.88% YoY. Revenue figure needs reconciliation - screener meta showed Rs.5,14,933cr which may be a different period/consolidated basis than the Rs.80,032cr profit figure.
A5: Tech Mahindra | B5: FY26 TTM | C5: 56815 | G5: 4806 | M5: 13.3 | S5: 25.3 | X5: 3.62 | Y5: Source: Screener.in consolidated, Jul-2026. 5yr sales growth only 8.46% (poor per screener). Payout ratio 112% exceeds EPS.
A6: Larsen & Toubro | B6: FY26 TTM | G6: 19147 | M6: 14.7 | N6: 17.85 | P6: 1.12 | S6: 33.8 | Y6: Source: Tijori Finance, Jun-2026. D/E elevated due to consolidated NBFC/financial-services arm - not a clean EPC-only leverage read. Net debt rising Rs.84,314cr (Mar-25) -> Rs.1,11,926cr (Sep-25).
A7: Tejas Networks | B7: FY26 | C7: 1103 | D7: -88 | G7: -909 | M7: -4.01 | N7: -4.83 | Y7: Source: Screener.in, MarketsMojo, Jul-2026. Revenue collapsed 88-90% YoY in multiple FY26 quarters; net loss vs FY25 profit of Rs.446cr. Debt/EBITDA ~7.94x.
A8: ACME Solar Holdings | B8: FY26 | C8: 2022.96 | D8: 43.97 | G8: 498.92 | M8: 8.4 | N8: 8.4 | P8: 0.65 | S8: 26 | Y8: Source: Tickertape/MarketsMojo, Jul-2026. Interest coverage thin (~1.15x). ROE/ROCE well below IOS 20% threshold despite strong topline growth.
A9: Atul Auto | B9: FY26 TTM | C9: 703 | M9: 5.72 | S9: 33 | Y9: Source: Screener.in/MoneyWorks4Me, Jul-2026. Revenue CAGR near-flat (0.65-2.86%). ROE well below IOS threshold.
A10: Mahindra Holidays | B10: Q4 FY26 | D10: -43.1 | G10: 41.55 | S10: 62.7 | Y10: Source: Groww/Tijori, Jul-2026. Q4 net profit fell 43.1% YoY on Mauritius impairment (~Rs.234cr) and soft EU (Holiday Club) performance. Altman Z-score only 0.83 - weakest of 8 peers.
A11: Power Finance Corporation | B11: FY26 | C11: 115444 | G11: 33625 | M11: 19.49 | S11: 6.5 | X11: 5.16 | Y11: Source: MarketsMojo/GuruFocus, Jul-2026. PFC-REC merger approved 28-Jun-2026 (88 PFC : 100 REC swap ratio) - pending integration, revisit all figures post-merger.
A12: ITC | B12: FY26 | C12: 78213.28 | G12: 20689.47 | M12: 35.2 | S12: 17.6 | X12: 5 | Y12: Source: Tickertape/Screener, Jul-2026. FY26 sales +4.77% YoY; note Q4 FY26 NP fell 73% YoY on exceptional items - use full-year figure for trend, not single quarter.
A13: Eicher Motors | B13: FY26 TTM | C13: 23408 | G13: 5515 | M13: 24 | S13: 38 | X13: 0.99 | Y13: Source: Screener.in, Jul-2026. Near debt-free; revenue CAGR ~15.6% vs ~13.4% industry median. Valuation rich (P/B ~8-9.6x).
A14: CreditAccess Grameen | B14: FY26 | C14: 6062.5 | G14: 777.6 | M14: 10.7 | O14: 2.7 | S14: 41.9 | Y14: Source: ICICI Direct/company guidance, Jul-2026. GNPA improved to 3.17% (60dpd). Q4 FY26 alone recovered to ROA 4.4%/ROE 17.8% - FY27 guidance ROE 16-20%. Trailing 3yr ROE only 13.8% (below threshold) - needs 1-2 more quarters to confirm recovery.
A15: Punjab National Bank | B15: FY26 | C15: 130772 | G15: 18467 | M15: 14.9 | O15: 0.9 | S15: 7.3 | Y15: Source: Screener.in/GuruFocus, Jul-2026. Net profit figure per screener meta (TTM basis) differs from FY25 Rs.18,553cr cited elsewhere - reconcile against BSE filing before using precisely. GNPA improved toward 4-5% post-2018-20 NPA cycle.

Sheet Decision Journal
A1: Company | B1: Decision Date | C1: Analyst | D1: Investment Thesis | E1: Variant Perception | F1: Supporting Evidence | G1: Disconfirming Evidence | H1: Key Risks | I1: Exit Conditions | J1: Review Date | K1: Outcome | L1: Lessons Learned
A2: CAMS | B2: Jul-2026 | C2: User | D2: Dominant RTA with strong cash generation | E2: Market underestimates durability | F2: High market share | G2: Loss of market share | H2: Regulation | I2: IOS score deterioration | J2: Oct-2026

Sheet Portfolio Tracker
A1: Company | B1: Ticker | C1: Buy Date | D1: Buy Price | E1: Quantity | F1: Investment Amount | G1: Current Price | H1: Current Value | I1: Unrealized P/L | J1: Return % | K1: Target Allocation % | L1: Actual Allocation % | M1: Rebalance Required | N1: Status
A2: Computer Age Management Services | B2: CAMS | G2: =IF(B2="","",IFERROR(VLOOKUP(B2&"*",'Master Universe'!$C:$AI,33,FALSE()),"")) | H2: =IF(OR(E2="",G2=""),"",ROUND(E2*G2,0)) | I2: =IF(OR(H2="",F2=""),"",H2-F2) | J2: =IF(OR(I2="",F2="",F2=0),"",ROUND(I2/F2*100,1)) | K2: 20% | L2: =IF(H2="","",ROUND(H2/SUM($H$2:$H$15)*100,1)) | M2: =IF(OR(L2="",K2=""),"",IF(ABS(L2-VALUE(SUBSTITUTE(K2,"%","")))>5,"Yes","No")) | N2: Core
