Workbook

Sheet Dashboard
A1: Metric | B1: Value
A2: Portfolio Name | B2: IOS v3.1
A3: As of Date | B3: July 2026 Baseline
A4: Total Universe | B4: 35
A5: Core Holdings | B5: 4
A6: Bench | B6: 1
A7: Research | B7: 26
A8: Deferred | B8: 4
A9: Cash Allocation Target | B9: 20%
A10: Review Frequency | B10: Quarterly
A11: Total Portfolio Value (Rs) | B11: 70000
A12: Required Margin of Safety (%) | B12: 25
A13: Default Growth Rate if Missing (%) | B13: 8
A14: Cost of Equity Ke (%) | B14: 13
A15: India 10Y G-Sec Yield Ref (%) | B15: 6.7
A16: Valuation Model | B16: Justified P/E (ROE-based): PE = (1 - g/ROE) x 100/(Ke-g); IV = Implied EPS x Justified PE
A17: Note | B17: Current Price values are manual snapshots entered in Master Universe - refresh periodically, not live-linked

Sheet Master Universe
A1: S.No | B1: Company | C1: Ticker | D1: Sector | E1: Industry | F1: Market Cap | G1: IOS Stage | H1: Evidence Gate | I1: Business Score | J1: Investment Score | K1: Data Confidence (%) | L1: Business Confidence (%) | M1: Research Priority | N1: Event Overlay | O1: Business Quality Notes | P1: Valuation (P/E) | Q1: PEG | R1: PEGY | S1: EV/EBIT | T1: ROE % | U1: ROCE % | V1: Debt/Equity | W1: FCF Yield % | X1: Revenue Growth % | Y1: EPS Growth % | Z1: Decision Journal | AA1: Last Reviewed | AB1: Next Review | AC1: Buy Price | AD1: Current Price | AE1: Intrinsic Value | AF1: Margin of Safety % | AG1: Target Allocation % | AH1: Position Size (₹) | AI1: Status | AJ1: Catalyst | AK1: Thesis Maturity | AL1: Remarks | AM1: Investment Thesis | AN1: Key Risks | AO1: Valuation Summary | AP1: Upgrade/Downgrade Trigger | AQ1: Sources Verified | AR1: EPS Implied (Rs, Price/PE) | AS1: Growth Rate Used % | AT1: Justified P/E | AU1: Dividend Yield | AV1: Beta | AW1: P/E | AX1: P/B | AY1: Investment Confidence (%) | AZ1: Risk Score (Engine) | BA1: Risk Confidence (%) | BB1: Portfolio Weight | BC1: Valuation Status | BD1: Overall Recommendation | BG1: Valuation Label | BH1: Score Status | BI1: Previous Close | BJ1: ROE Reconciliation Status | BK1: ROE Reconciliation Note | BL1: Gross NPA % | BM1: Net NPA % | BN1: CAR % | BO1: PCR % | BP1: Business Risk | BQ1: Financial Risk | BR1: Valuation Risk | BS1: Governance Risk | BT1: Total Risk
A2: 1 | B2: Computer Age Management Services (CAMS) | C2: CAMS.NS | D2: Technology | E2: Information Technology Services | F2: 195994877952 | G2: Core | H2: Pass | I2: 97 | J2: 47.713924 | K2: 97 | L2: 100 | M2: Low - thesis proven, maintenance only | N2: None | O2: Dominant mutual fund RTA | Debt/Equity ~0.05 (near-zero net cash). | P2: 40 | Q2: 2 | R2: 1.85 | S2: 33.173574 | T2: 36.031699 | U2: 41.205615 | V2: 0.05 | W2: 2.2579022 | X2: 16 | Y2: 20 | Z2: Complete | AA2: Jul-2026 | AB2: Oct-2026 | AC2: 417.34614 | AD2: 752 | AE2: 521.68268 | AF2: -51.365961 | AG2: 5.8182822 | AH2: 58182.822 | AI2: Core | AJ2: Market leadership | AK2: Validated | AL2: See structured fields (Thesis / Risks / Valuation / Trigger / Sources) for detail. | AM2: Dominant RTA franchise (~65% mutual-fund AUM market share moat); high-margin, asset-light business compounding with AUM growth. | AN2: Regulatory/SEBI fee-structure changes; AUM-linked revenue exposed to market downturns. | AO2: P/E ~40x (near 10yr median); ROCE ~53-60%; ROE ~20-25%; net cash (~Rs.885M debt vs ~Rs.6.8B cash); gross margin ~65%, op margin ~40%. | AP2: Core holding, already promoted. Downgrade trigger: AUM market-share loss or regulatory fee cap. | AQ2: Screener/GuruFocus aggregation, Jul-2026. | AR2: 19.779999 | AS2: 13.813758 | AT2: 26.374251 | AU2: 1.67 | AV2: 0.133 | AW2: 39.92164 | AX2: 14.824655 | AY2: 100 | AZ2: 1.6207763 | BA2: 100 | BC2: OK | BD2: Watch (Quality, Pricey) | BG2: Significantly Overvalued | BH2: Scored | BQ2: 1.6207763 | BT2: 1.6207763
A3: 2 | B3: Tata Consultancy Services | C3: TCS.NS | D3: Technology | E3: Information Technology Services | F3: 7527793164288 | G3: Core | H3: Pass | I3: 74 | J3: 100 | K3: 95 | L3: 100 | M3: Low - maintenance, USFDA/deal-win monitoring | N3: None | O3: High FCF and zero debt | P3: 18.6 | Q3: 2.33 | R3: 1.66 | S3: 11.323078 | T3: 45.364037 | U3: 55.181215 | V3: 0.11 | W3: 6.318131 | X3: 6 | Y3: 8 | Z3: Complete | AA3: Jul-2026 | AB3: Oct-2026 | AC3: 3352.4064 | AD3: 1983 | AE3: 4190.508 | AF3: 50.349695 | AG3: 12.194097 | AH3: 121940.97 | AI3: Core | AJ3: AI & digital | AK3: Validated | AL3: See structured fields (Thesis / Risks / Valuation / Trigger / Sources) for detail. | AM3: Largest Indian IT services franchise; AI-services growth narrative; deep valuation discount vs peers. | AN3: ROE/ROCE not independently re-verified this session (pending); global IT spending slowdown; stock down ~55% off ATH signals sentiment risk. | AO3: P/E ~18.6x vs Coforge ~36-38x; trading ~Rs.2,050-2,100 vs Aug-2024 ATH Rs.4,592. | AP3: Verify current ROE/ROCE from primary source. | AQ3: Session verification, Jul-2026 (ROE/ROCE pending). | AR3: 135.47 | AS3: 25 | AT3: 30.933107 | AU3: 6.03 | AV3: 0.241 | AW3: 15.358382 | AX3: 7.0195684 | AY3: 100 | AZ3: 3.4670624 | BA3: 100 | BC3: OK | BD3: Strong Buy | BG3: Undervalued | BH3: Scored | BQ3: 3.4670624 | BT3: 3.4670624
A4: 3 | B4: Lupin | C4: LUPIN.NS | D4: Healthcare | E4: Drug Manufacturers - Specialty & Generic | F4: 1144641814528 | G4: Core | H4: Pass | I4: 94 | J4: 100 | K4: 94 | L4: 100 | M4: Low - minor pipeline monitoring | N4: None | O4: Turnaround | P4: 21 | Q4: 0.57 | R4: 0.56 | S4: 7.9676745 | T4: 23.687436 | U4: 57.096423 | V4: 0.29 | W4: 4.5133804 | X4: 23 | Y4: 37 | Z4: Complete | AA4: Jul-2026 | AB4: Oct-2026 | AC4: 2585.5345 | AD4: 2476 | AE4: 3231.9181 | AF4: 22.53826 | AG4: 12.194097 | AH4: 121940.97 | AI4: Core | AJ4: USFDA compliance | AK4: Established | AL4: See structured fields (Thesis / Risks / Valuation / Trigger / Sources) for detail. | AM4: Pharma turnaround story; margin expansion from product mix-shift; strengthening balance sheet. | AN4: ROE/P/E figure sourced from unverified ML screen; mix-shift durability unconfirmed. | AO4: ROCE 28.4%; revenue growth 23% (FY26); Q4 FY26 gross margin 75% (up from 61.7% YoY); net cash ~Rs.4,600cr. | AP4: Confirm ROE/P/E against primary source (currently ML-screen only). | AQ4: FY26 results search this session, Jul-2026; ROE/P/E via ML Alpha screen (unverified). | AR4: 116.56466 | AS4: 24.132888 | AT4: 27.727506 | AU4: 0.49 | AV4: 0.18 | AW4: 21.47735 | AX4: 5.095596 | AY4: 100 | AZ4: 9.7959272 | BA4: 100 | BC4: OK | BD4: Strong Buy | BG4: Undervalued | BH4: Scored | BJ4: Conflict | BK4: ROE conflict: automated engine shows 23.69, Financial Data sheet shows 29.10 (18.6% relative variance, threshold 15%). | BQ4: 9.7959272 | BT4: 9.7959272
A5: 4 | B5: Nesco | C5: NESCO.NS | D5: Industrials | E5: Conglomerates | F5: 77386178560 | G5: Core | H5: Pass | I5: 45 | J5: 21.819888 | K5: 92 | L5: 100 | M5: Low - stable annuity economics | N5: None | O5: Asset-backed cash flow | P5: 19.8 | Q5: 1.24 | R5: 1.2 | T5: 13.774437 | U5: 12.944575 | V5: 0 | X5: 13 | Y5: 16 | Z5: Complete | AA5: Jul-2026 | AB5: Oct-2026 | AC5: 320.96379 | AD5: 1149 | AE5: 401.20474 | AF5: -173.75051 | AG5: 2.6607384 | AH5: 26607.384 | AI5: Core | AJ5: Occupancy | AK5: Established | AL5: See structured fields (Thesis / Risks / Valuation / Trigger / Sources) for detail. | AM5: Zero-debt commercial real estate/exhibition-center operator; high-margin annuity-like business. | AN5: Current P/E, ROE, revenue growth not independently pulled - re-rating risk unassessed. | AO5: ROCE ~20-22%; operating margins ~60%; zero debt. | AP5: Pull current P/E/ROE/revenue growth from primary source. | AQ5: Multiple sources this session, Jul-2026 (P/E/ROE/growth pending). | AR5: 58.56 | AS5: 13.044297 | AT5: 6.8511738 | AU5: 0.64 | AV5: 0.509 | AW5: 18.755123 | AX5: 2.581854 | AY5: 100 | AZ5: 3.0227182 | BA5: 100 | BC5: OK | BD5: Avoid | BG5: Significantly Overvalued | BH5: Scored | BQ5: 3.0227182 | BT5: 3.0227182
A6: 5 | B6: Persistent Systems | C6: PERSISTENT.NS | D6: Technology | E6: Information Technology Services | F6: 776327659520 | G6: Bench | H6: Pass | I6: 85 | J6: 41.637028 | K6: 7 | L6: 100 | M6: Low - thesis proven, monitor Nagarro integration | N6: Active | O6: IT services, US$1bn+ revenue, active M&A strategy | P6: 38.7 | Q6: 1.06 | R6: 1.04 | S6: 32.198756 | T6: 23.796307 | U6: 28.305862 | V6: 0.06 | W6: 2.0231621 | X6: 19.6 | Y6: 35.9 | Z6: Pending | AA6: Jul-2026 | AB6: Oct-2026 | AC6: 2250.1624 | AD6: 4683 | AE6: 2812.703 | AF6: -76.66636 | AG6: 5.0772597 | AH6: 50772.597 | AI6: Bench | AJ6: Integration | AK6: Developing | AL6: See structured fields (Thesis / Risks / Valuation / Trigger / Sources) for detail. | AM6: IT services + Nagarro-style digital engineering growth compounder; historically high ROCE. | AN6: Nagarro acquisition integration risk - do not score until integration clarity. | AO6: P/E 38.7x; 3yr ROE 25.4%; net debt-free; ROCE ~20% and rising (exact current figure pending); 10yr median sales growth 19.6%. | AP6: Nagarro integration clarity before scoring. | AQ6: Verified 2026-07 (Tijori + others). | AR6: 120.26 | AS6: 18.146558 | AT6: 23.388517 | AU6: 0.92 | AV6: 0.121 | AW6: 41.31964 | AX6: 9.918542 | AY6: 100 | AZ6: 2.0305215 | BA6: 100 | BC6: OK | BD6: Watch (Quality, Pricey) | BG6: Significantly Overvalued | BH6: Scored | BQ6: 2.0305215 | BT6: 2.0305215
A7: 6 | B7: RR Kabel | C7: RRKABEL.NS | D7: Industrials | E7: Electrical Equipment & Parts | F7: 251128152064 | G7: Research | H7: Pass | I7: 58.5 | J7: 27.973578 | K7: 70 | L7: 100 | M7: Medium - confirm FY27 EPS growth guidance (~11%) | N7: None | O7: Cables & FMEG manufacturer; strong brand, electrification tailwind | P7: 46 | Q7: 0.74 | R7: 4.07 | T7: 19.119761 | U7: 25.476861 | V7: 0.08 | X7: 28 | Y7: 11 | Z7: Not started | AA7: Jul-2026 | AB7: Oct-2026 | AC7: 142.93877 | AD7: 2450 | AE7: 178.67346 | AF7: -1142.658 | AG7: 3.4111253 | AH7: 34111.253 | AI7: Research | AJ7: Watch | AK7: Early | AL7: See structured fields (Thesis / Risks / Valuation / Trigger / Sources) for detail. | AM7: Wire & cable manufacturer; strong ROE/ROCE; zero long-term debt; no promoter pledge. | AN7: Richly valued relative to own history (downgraded Fair-from-Attractive Oct-2025); recent all-time-high raises valuation-discipline concern. | AO7: P/E ~46x (peer median ~50x); ROE 19.7%; ROCE 20.47% avg; PEG 0.74; net D/E 0.08; 5yr rev CAGR 15.1%, TTM growth 28%. | AP7: Valuation-discipline check before promotion (Business Confidence pending). | AQ7: Verified 2026-07. | AR7: 43.909999 | AS7: 17.23768 | AT7: 4.0690836 | AU7: 0.5 | AV7: 1.45 | AW7: 50.564793 | AX7: 9.754844 | AY7: 100 | AZ7: 4.3638364 | BA7: 100 | BC7: OK | BD7: Avoid | BG7: Extreme Premium | BH7: Scored | BQ7: 4.3638364 | BT7: 4.3638364
A8: 7 | B8: Cummins India | C8: CUMMINSIND.NS | D8: Industrials | E8: Specialty Industrial Machinery | F8: 1569645002752 | G8: Research | H8: Pass | I8: 89.5 | J8: 44.685741 | K8: 80 | L8: 100 | M8: Low - monitor quarterly, high valuation | N8: None | O8: Diesel/alt-fuel engines & gensets; 51% Cummins Inc-backed, near debt-free, high-ROCE compounder | P8: 64.3 | Q8: 2.09 | R8: 2.05 | S8: 65.308073 | T8: 27.866731 | U8: 27.033079 | V8: 0.003 | W8: 0.94731024 | X8: 13 | Y8: 30.8 | Z8: Not started | AA8: Jul-2026 | AB8: Oct-2026 | AC8: 1381.0545 | AD8: 5478 | AE8: 1726.3181 | AF8: -228.01023 | AG8: 5.4490227 | AH8: 54490.227 | AI8: Research | AJ8: Watch | AK8: Early | AL8: See structured fields (Thesis / Risks / Valuation / Trigger / Sources) for detail. | AM8: Diesel/alt-fuel engines & gensets; 51% Cummins Inc-backed; high-ROCE compounder. | AN8: Valuation re-rated hard (+95% 1yr) - entry discipline needed; PEG likely expensive given re-rating. | AO8: P/E 64.3x; ROCE 36.3%; ROE 28.2% (3yr 26.3%); near debt-free; 5yr sales growth 15%, TTM 13%; 5yr profit CAGR 22% (3yr 35%). | AP8: Entry-price discipline check before promotion; DC/BC not yet scored. | AQ8: Verified 2026-07 (Screener). | AR8: 85.910008 | AS8: 10.960206 | AT8: 20.094495 | AU8: 1.2 | AV8: 0.572 | AW8: 65.911995 | AX8: 18.519972 | AY8: 100 | AZ8: 0.14359611 | BA8: 100 | BC8: OK | BD8: Watch (Quality, Pricey) | BG8: Significantly Overvalued | BH8: Scored | BJ8: OK | BK8: ROE matches within tolerance (1.2% variance). | BQ8: 0.14359611 | BT8: 0.14359611
A9: 8 | B9: MTAR Technologies | C9: MTARTECH.NS | D9: Industrials | E9: Specialty Industrial Machinery | F9: 213748400128 | G9: Research | H9: Fail | I9: 44.5 | J9: 0 | K9: 55 | L9: 100 | M9: Low - high valuation, weak ROE/ROCE vs threshold | N9: None | O9: Precision components: nuclear, space, defense, clean energy | P9: 190 | Q9: 2.49 | R9: 2.49 | S9: 159.71691 | T9: 11.43101 | U9: 13.395915 | V9: 0.3 | W9: 0.29102901 | X9: 29.6 | Y9: 76.2 | Z9: Not started | AA9: Jul-2026 | AB9: Jan-2027 | AC9: 492.57349 | AD9: 7034 | AE9: 615.71687 | AF9: -1028.6032 | AG9: 0.67232619 | AH9: 6723.2619 | AI9: Research | AJ9: Watch | AK9: Early | AL9: See structured fields (Thesis / Risks / Valuation / Trigger / Sources) for detail. | AM9: AI/defense/clean-energy narrative stock. | AN9: Client concentration (Bloom Energy exposure); valuation entirely narrative-driven, not supported by returns. | AO9: P/E ~190-258x (peer median ~34x); ROE only 7.26%; ROCE only 11.16% - both fail 20% threshold. | AP9: N/A - excluded outright, fails core profitability gate. | AQ9: Verified 2026-07. | AR9: 31.22 | AS9: 12.121 | AT9: 19.721873 | AV9: 1.099 | AW9: 222.58168 | AX9: 25.978542 | AY9: 75 | AZ9: 15.259379 | BA9: 75 | BC9: OK | BD9: Avoid | BG9: Extreme Premium | BH9: Scored | BQ9: 15.259379 | BT9: 15.259379
A10: 9 | B10: Aegis Logistics | C10: AEGISLOG.NS | D10: Energy | E10: Oil & Gas Refining & Marketing | F10: 443874607104 | G10: Research | H10: Conflict | I10: 27.5 | J10: 11.584715 | K10: 55 | L10: 100 | M10: Blocked - resolve ROCE conflict (24.93% vs 15.37%) before scoring | N10: None | O10: LPG/gas logistics & storage; infrastructure-like moat | P10: 39 | Q10: 1.18 | R10: 1.13 | S10: 38.925296 | T10: 10.224468 | U10: 11.363537 | V10: 0.1 | W10: 2.4752487 | X10: -0.1 | Y10: 33 | Z10: Not started | AA10: Jul-2026 | AB10: Sep-2026 | AC10: 651.42017 | AD10: 1325 | AE10: 814.27521 | AF10: -55.303758 | AG10: 0.53901457 | AH10: 5390.1457 | AI10: Research (Blocked) | AJ10: Watch | AK10: Early | AL10: See structured fields (Thesis / Risks / Valuation / Trigger / Sources) for detail. | AM10: Logistics/energy-storage business with historically strong ROCE claims. | AN10: ROCE conflict unresolved (24.93% vs 15.37% across sources); revenue deceleration (-0.1% FY25 vs 5yr CAGR 28.2%); WACC 12.42% vs ROIC ~10.34% (one source implies value destruction). | AO10: ROE 20.43%; D/E 0.10 (above sector avg 0.03); P/E ~39x vs peer median ~23x. | AP10: Resolve ROCE conflict via primary source before scoring. | AQ10: moneyworks4me, GuruFocus, other tracker (conflicting), Jul-2026. | AR10: 25.530001 | AS10: 10.48835 | AT10: 31.894838 | AU10: 1.08 | AV10: 0.572 | AW10: 49.53388 | AX10: 7.3316097 | AY10: 100 | AZ10: 15.747529 | BA10: 100 | BC10: OK | BD10: Avoid | BG10: Significantly Overvalued | BH10: Scored | BQ10: 15.747529 | BT10: 15.747529
A11: 10 | B11: Neuland Laboratories | C11: NEULANDLAB.NS | D11: Healthcare | E11: Drug Manufacturers - Specialty & Generic | F11: 250824327168 | G11: Research | H11: Conflict | I11: 73.5 | J11: 34.781135 | K11: 70 | L11: 100 | M11: Monitor - working capital / FCF trend | N11: None | O11: API/CDMO pharma manufacturer | P11: 64 | Q11: 1.73 | R11: 1.66 | S11: 52.421749 | T11: 19.418707 | U11: 21.74646 | V11: 0.4 | W11: -0.1993584 | X11: 37 | Y11: 37 | Z11: Not started | AA11: Jul-2026 | AB11: Oct-2026 | AC11: 1489.6675 | AD11: 18944 | AE11: 1862.0844 | AF11: -949.89872 | AG11: 1.1458998 | AH11: 11458.998 | AI11: Research | AJ11: Watch | AK11: Early | AL11: See structured fields (Thesis / Risks / Valuation / Trigger / Sources) for detail. | AM11: Pharma API/CDMO manufacturer; strong revenue growth and margins. | AN11: Negative FCF (-Rs.49.4cr) from working-capital build; Tijori flags WC dragging ROCE/ROE; promoter holding declining (-3.5% 3yr); company self-warns of 'irregular earnings patterns.' | AO11: P/E 64-95x (conflicting, unresolved); FY26 revenue +37%; Q4 EBITDA margin 40.5%. | AP11: Resolve P/E conflict via Screener; follow up on working-capital and promoter-selling trend. | AQ11: Verified 2026-07 (conflicting across sources). | AR11: 293.13002 | AS11: 10 | AT11: 6.3524183 | AU11: 0.18 | AV11: -0.321 | AW11: 66.693954 | AX11: 13.390219 | AY11: 50 | AZ11: 5.3574563 | BA11: 50 | BC11: OK | BD11: Avoid | BG11: Extreme Premium | BH11: Scored | BQ11: 5.3574563 | BT11: 5.3574563
A12: 11 | B12: Elecon Engineering | C12: ELECON.NS | D12: Industrials | E12: Specialty Industrial Machinery | F12: 116553334784 | G12: Research | H12: Pass | I12: 44.5 | J12: 21.373025 | K12: 70 | L12: 100 | M12: Monitor - order-book/execution recovery after Q4 FY26 miss | N12: None | O12: Industrial gears/material handling equipment | P12: 35.19 | Q12: 2.01 | R12: 1.85 | S12: 27.398824 | T12: 14.795106 | U12: 16.713269 | V12: 0.12 | W12: 1.6557878 | X12: 17.5 | Y12: 17.5 | Z12: Not started | AA12: Jul-2026 | AB12: Oct-2026 | AC12: 187.0706 | AD12: 529 | AE12: 233.83825 | AF12: -122.11935 | AG12: 2.6062475 | AH12: 26062.475 | AI12: Research | AJ12: Watch | AK12: Early | AL12: See structured fields (Thesis / Risks / Valuation / Trigger / Sources) for detail. | AM12: Industrial gear/power-transmission manufacturer; net cash position. | AN12: ROE below 20% IOS threshold; stock down -17.9% 52wk despite decent fundamentals. | AO12: P/E 35.2x; ROE 15.85%; ROIC 18.21%; D/E 0.12; net cash. | AP12: ROE needs to clear 20% threshold to qualify as core-quality candidate. | AQ12: Verified 2026-07. | AR12: 15.189999 | AS12: 13.765009 | AT12: 15.394223 | AU12: 0.4 | AV12: 0.489 | AW12: 34.19355 | AX12: 5.054693 | AY12: 100 | AZ12: 3.9414585 | BA12: 100 | BC12: OK | BD12: Avoid | BG12: Significantly Overvalued | BH12: Scored | BQ12: 3.9414585 | BT12: 3.9414585
A13: 12 | B13: State Bank of India | C13: SBIN.NS | D13: Financial Services | E13: Banks - Regional | F13: 9477074976768 | G13: Research | H13: Pass | I13: 23.333333 | J13: 14.139393 | K13: 75 | L13: 60 | M13: Medium - standard quarterly monitoring (bank; ROCE/D-E not standard metrics) | N13: None | O13: Largest PSU bank by assets; ~22% deposit share, ~20% net advance share | ROCE/Debt-Equity shown are mechanically computed (Tijori/StockViz) - not economically standard metrics for a deposit-funded bank / borrowings-funded NBFC balance sheet; included per request, interpret with that context. | P13: 11.6 | Q13: 0.89 | R13: 0.8 | T13: 13.546739 | U13: 13.76 | V13: 1.33 | W13: 2.897374 | X13: 5.2 | Y13: 13 | Z13: Not started | AA13: Jul-2026 | AB13: Oct-2026 | AC13: 829.62022 | AD13: 1040 | AE13: 1037.0253 | AF13: 0.99566334 | AG13: 1.0345028 | AH13: 10345.028 | AI13: Research | AJ13: Watch | AK13: Early | AL13: See structured fields (Thesis / Risks / Valuation / Trigger / Sources) for detail. | AM13: Largest PSU bank by assets; strong profit growth; cheap valuation. | AN13: Bank-specific yardstick applied (ROE>15%, not 20% threshold) - judgment call on cross-comparability; ROCE/D-E not meaningful for banks. | AO13: FY26 net profit Rs.80,032cr (+12.88% YoY); ROA 1.12%; ROE 18.57%; P/E ~11.6x; advances +16.87% YoY; deposits +11.03% YoY. | AP13: DC/BC not yet formally scored - first-pass research only. | AQ13: Verified 2026-07 (GuruFocus). | AR13: 91.580009 | AS13: 12.777811 | AT13: 11.323709 | AU13: 1.71 | AV13: 0.362 | AW13: 11.210962 | AX13: 1.5897644 | AY13: 60 | AZ13: 40 | BA13: 100 | BC13: Missing EV/EBIT (EBIT <= 0) | BD13: Avoid | BG13: Fair Value | BH13: Scored | BJ13: Conflict | BK13: ROE conflict: automated engine shows 13.55, Financial Data sheet shows 18.57 (27.1% relative variance, threshold 15%). | BQ13: 40 | BT13: 40
A14: 13 | B14: Titan Company | C14: TITAN.NS | D14: Consumer Cyclical | E14: Luxury Goods | F14: 4059207827456 | G14: Research | H14: Conflict | I14: 72 | J14: 12.599885 | K14: 50 | L14: 100 | M14: Blocked - resolve ROCE conflict (20-21% vs 37.37%) and D/E conflict (0 vs 1.56) | N14: None | O14: Jewellery/watches/eyewear lifestyle major, Tata Group | P14: 76.5 | Q14: 5.1 | R14: 4.64 | T14: 32.305929 | U14: 36.373267 | V14: 1.5 | X14: 17 | Y14: 15 | Z14: Not started | AA14: Jul-2026 | AB14: Sep-2026 | AC14: 1239.5939 | AD14: 3550 | AE14: 1549.4924 | AF14: -195.32897 | AG14: =IF(H14="Fail","Not Eligible (Failed Gate)",IF(J14="","Pending Score",IF(J14>=90,"10%",IF(J14>=80,"7.5%",IF(J14>=70,"5%","Watchlist only"))))) -> Watchlist only | AH14: =IFERROR(ROUND(VALUE(SUBSTITUTE(AG14,"%",""))/100*Dashboard!$B$11,0),"") | AI14: Research (Blocked) | AJ14: Watch | AK14: Early | AL14: See structured fields (Thesis / Risks / Valuation / Trigger / Sources) for detail. | AM14: Dominant jewelry/watches consumer franchise; strong headline ROE. | AN14: ROCE conflict (20-21% vs 37.37% across sources); D/E conflict (0 vs 1.56, likely Ind AS 116 lease treatment); Piotroski F-Score only 2/9 despite headline quality - notable red flag; P/E 76.5x vs industry median 21.6x, very rich. | AO14: ROE 28.7-37.7% (range, all periods strong). | AP14: Resolve ROCE and D/E conflicts before scoring. | AQ14: Verified 2026-07 (multiple, conflicting). | AR14: 56.950001 | AS14: 25 | AT14: 27.207944 | AU14: 0.33 | AV14: 0.219 | AW14: 80.35294 | AX14: 25.871944 | AY14: 100 | AZ14: 65.000318 | BA14: 100 | BC14: OK | BD14: Avoid | BG14: Significantly Overvalued | BH14: Scored | BQ14: 65.000318 | BT14: 65.000318
A15: 14 | B15: Tech Mahindra | C15: TECHM.NS | D15: Technology | E15: Information Technology Services | F15: 1287188381696 | G15: Research | H15: Fail | I15: 62 | J15: 0 | K15: 75 | L15: 100 | M15: Low - weak 5yr growth (8.5%), payout exceeds EPS | N15: None | O15: IT services subsidiary of Mahindra Group; telecom-heavy client mix | P15: 25.3 | Q15: 3.16 | R15: 2.66 | S15: 17.098301 | T15: 15.995279 | U15: 21.185826 | V15: 0.1 | W15: 4.3352412 | X15: 8.46 | Y15: 8 | Z15: Not started | AA15: Jul-2026 | AB15: Oct-2026 | AC15: 720.51293 | AD15: 1410 | AE15: 900.64116 | AF15: -61.340617 | AG15: 2.136006 | AH15: 21360.06 | AI15: Research | AJ15: Watch | AK15: Early | AL15: See structured fields (Thesis / Risks / Valuation / Trigger / Sources) for detail. | AM15: IT services subsidiary of Mahindra Group. | AN15: ROE well below 20% threshold; weak 5yr sales growth (8.46%); dividend payout 112% exceeds earnings. | AO15: P/E ~25.3x; 3yr ROE 13.3%. | AP15: N/A - excluded, no differentiated catalyst vs TCS. | AQ15: Verified 2026-07 (Screener/GuruFocus). | AR15: 54.060001 | AS15: 5 | AT15: 16.660029 | AU15: 3.57 | AV15: 0.173 | AW15: 26.879393 | AX15: 4.3452907 | AY15: 100 | AZ15: 2.4228924 | BA15: 100 | BC15: OK | BD15: Avoid | BG15: Significantly Overvalued | BH15: Scored | BJ15: Conflict | BK15: ROE conflict: automated engine shows 16.00, Financial Data sheet shows 13.30 (16.9% relative variance, threshold 15%). | BQ15: 2.4228924 | BT15: 2.4228924
A16: 15 | B16: Larsen & Toubro | C16: LT.NS | D16: Industrials | E16: Engineering & Construction | F16: 5409091878912 | G16: Research | H16: Conflict | I16: 27 | J16: 9.1062035 | K16: 55 | L16: 100 | M16: Blocked - need segment-level D/E excluding financial-services arm | N16: None | O16: Diversified EPC conglomerate: infra, hydrocarbon, defence, IT, financial services | P16: 33.8 | Q16: 2.82 | R16: 2.5 | S16: 24.759569 | T16: 12.513757 | U16: 13.66839 | V16: 1.12 | W16: 1.7801834 | X16: 12 | Y16: 12 | Z16: Not started | AA16: Jul-2026 | AB16: Sep-2026 | AC16: 1887.8027 | AD16: 3693 | AE16: 2359.7534 | AF16: -66.619105 | AG16: 0.028337754 | AH16: 283.37754 | AI16: Research (Blocked) | AJ16: Watch | AK16: Early | AL16: See structured fields (Thesis / Risks / Valuation / Trigger / Sources) for detail. | AM16: Diversified EPC conglomerate (infra, hydrocarbon, defence, IT, financial services). | AN16: ROE/ROCE both below 20% threshold; D/E elevated (1.12-1.41) but distorted by NBFC arm - needs segment-level resolution; net debt rising sharply. | AO16: P/E ~33.8x; ROE ~14.7-15%; ROCE ~17.85%. | AP16: Segment-level D/E excluding financial-services arm needed before scoring. | AQ16: Verified 2026-07 (Tijori/Screener). | AR16: 116.58 | AS16: 12.020662 | AT16: 20.241494 | AU16: 0.98 | AV16: 0.46 | AW16: 33.726196 | AX16: 4.94896 | AY16: 100 | AZ16: 32.54664 | BA16: 100 | BC16: OK | BD16: Avoid | BG16: Significantly Overvalued | BH16: Scored | BJ16: OK | BK16: ROE matches within tolerance (14.9% variance). | BQ16: 32.54664 | BT16: 32.54664
A17: 16 | B17: Avalon Technologies | C17: AVALON.NS | D17: Technology | E17: Electronic Components | F17: 115824861184 | G17: Research | H17: Fail | I17: 41 | J17: 0 | K17: 70 | L17: 100 | M17: Low priority - structural Fail (ROE/ROCE below threshold), revisit only if fundamentals improve | N17: None | O17: EMS/electronics manufacturing, PCB to box-build | P17: 100 | Q17: 2.05 | R17: 1.99 | T17: 15.649885 | U17: 18.182954 | V17: 0.15 | X17: 18.4 | Y17: 48.7 | Z17: Not started | AA17: Jul-2026 | AB17: Jan-2027 | AC17: 51.870325 | AD17: 1800 | AE17: 64.837907 | AF17: -2573.7446 | AG17: 0.80538115 | AH17: 8053.8115 | AI17: Research (Low priority) | AJ17: Watch | AK17: Early | AL17: See structured fields (Thesis / Risks / Valuation / Trigger / Sources) for detail. | AM17: EMS (electronics manufacturing services) upcycle narrative stock. | AN17: ROE/ROCE fail 20% threshold by wide margin; P/E swung 76x-134x on pure re-rating (+118% 1yr) - narrative priced in well ahead of fundamentals. | AO17: ROE ~9-11% (3yr); ROCE avg 12.4%. | AP17: N/A - excluded, same pattern as MTAR. | AQ17: Verified 2026-07. | AR17: 16.799998 | AS17: 16.943 | AT17: 3.8593992 | AW17: 103.19048 | AX17: 16.0468 | AY17: 75 | AZ17: 9.8342582 | BA17: 75 | BC17: OK | BD17: Avoid | BG17: Extreme Premium | BH17: Scored | BQ17: 9.8342582 | BT17: 9.8342582
A18: 17 | B18: CG Power and Industrial Solutions | C18: CGPOWER.NS | D18: Industrials | E18: Electrical Equipment & Parts | F18: 1450555867136 | G18: Research | H18: Fail | I18: 40.5 | J18: 0 | K18: 60 | L18: 100 | M18: Monitor - rich valuation vs order backlog growth | N18: None | O18: Electrical equipment, electrification/industrial capex play | P18: 121 | Q18: 4.03 | R18: 3.84 | S18: 100.40008 | T18: 14.71375 | U18: 17.067301 | V18: 0.1 | W18: -0.051901705 | X18: 25 | Y18: 30 | Z18: Not started | AA18: Jul-2026 | AB18: Oct-2026 | AC18: 64.214445 | AD18: 965 | AE18: 80.268056 | AF18: -1047.4054 | AG18: 0.74145632 | AH18: 7414.5632 | AI18: Research | AJ18: Watch | AK18: Early | AL18: See structured fields (Thesis / Risks / Valuation / Trigger / Sources) for detail. | AM18: Power equipment 'supercycle' narrative stock. | AN18: ROCE flagged as decreasing even without significant capex (unexplained); extreme valuation. | AO18: P/E ~121x (~200% premium to peer median ~40x); P/B ~18x vs peer median ~4.6x. | AP18: N/A - excluded, priced for flawless multi-year supercycle with no margin for error. | AQ18: Session check, Jul-2026. | AR18: 7.7399998 | AS18: 16.259103 | AT18: 10.37055 | AU18: 0.14 | AV18: 0.407 | AW18: 118.99225 | AX18: 18.198343 | AY18: 50 | AZ18: 0.4818508 | BA18: 50 | BC18: OK | BD18: Avoid | BG18: Extreme Premium | BH18: Scored | BQ18: 0.4818508 | BT18: 0.4818508
A19: 18 | B19: Tejas Networks | C19: TEJASNET.NS | D19: Technology | E19: Communication Equipment | F19: 97688657920 | G19: Research | H19: Fail | I19: 0 | J19: 0 | K19: 70 | L19: 90 | M19: Monitor - loss-making, order lumpiness (BSNL contracts) | N19: None | O19: Wireline/wireless telecom equipment; Tata Group (Panatone Finvest) promoted | P19: N/A (loss-making) | T19: -31.010928 | U19: -29.36837 | V19: 0.9 | W19: -5.4084059 | X19: -88 | Y19: -88 | Z19: Not started | AA19: Jul-2026 | AB19: Oct-2026 | AD19: 602 | AF19: =IF(OR(NOT(ISNUMBER(AE19)),AE19<=0,AD19=""),"",ROUND((AE19-AD19)/AE19*100,1)) | AG19: =IF(H19="Fail","Not Eligible (Failed Gate)",IF(J19="","Pending Score",IF(J19>=90,"10%",IF(J19>=80,"7.5%",IF(J19>=70,"5%","Watchlist only"))))) -> Not Eligible (Failed Gate) | AH19: =IFERROR(ROUND(VALUE(SUBSTITUTE(AG19,"%",""))/100*Dashboard!$B$11,0),"") | AI19: Research (Weak) | AJ19: Watch | AK19: Early | AL19: See structured fields (Thesis / Risks / Valuation / Trigger / Sources) for detail. | AM19: Telecom equipment manufacturer, Tata-promoted. | AN19: FY26 net loss ~Rs.909cr; revenue collapse 88-90% YoY; negative ROE/ROCE; Debt/EBITDA ~7.94x while loss-making. | AO19: N/A - loss-making, no meaningful P/E. | AP19: N/A - excluded, capital destruction in progress. | AQ19: Verified 2026-07. | AR19: =IFERROR(ROUND(AD19/P19,2),"N/A") -> N/A | AS19: 5 | AT19: =IFERROR(IF(OR(T19="",T19=0,AR19="N/A",T19-AS19<3),"N/A",ROUND((1-(AS19/T19))*100/(Dashboard!$B$14-AS19),1)),"N/A") -> N/A | AU19: 0.42 | AV19: -0.26 | AX19: 3.335456 | AY19: 0 | AZ19: 47.506713 | BA19: 0 | BC19: Invalid Inputs | Missing EV/EBIT (EBIT <= 0) | BD19: Avoid | BH19: Confirmed Weak Fundamentals | BJ19: Conflict | BK19: ROE conflict: automated engine shows -31.01, Financial Data sheet shows -4.01 (87.1% relative variance, threshold 15%). | BQ19: 47.506713 | BT19: 47.506713
A20: 19 | B20: ACME Solar Holdings | C20: ACMESOLAR.NS | D20: Utilities | E20: Utilities - Renewable | F20: 262528548864 | G20: Research | H20: Fail | I20: 35 | J20: 0 | K20: 65 | L20: 100 | M20: Monitor - ROE/ROCE below 20% threshold despite strong topline growth | N20: None | O20: Solar/wind/hybrid/FDRE + BESS developer-operator; PPA-based revenue | P20: 26 | Q20: 0.59 | R20: 0.57 | S20: 33.436695 | T20: 9.8596529 | U20: 5.1873073 | V20: 0.65 | W20: -9.2734545 | X20: 42.3 | Y20: 44 | Z20: Not started | AA20: Jul-2026 | AB20: Oct-2026 | AC20: 53.835017 | AD20: 270 | AE20: 67.293771 | AF20: -452.35425 | AG20: =IF(H20="Fail","Not Eligible (Failed Gate)",IF(J20="","Pending Score",IF(J20>=90,"10%",IF(J20>=80,"7.5%",IF(J20>=70,"5%","Watchlist only"))))) -> Not Eligible (Failed Gate) | AH20: =IFERROR(ROUND(VALUE(SUBSTITUTE(AG20,"%",""))/100*Dashboard!$B$11,0),"") | AI20: Research | AJ20: Watch | AK20: Early | AL20: See structured fields (Thesis / Risks / Valuation / Trigger / Sources) for detail. | AM20: Solar/wind/hybrid/FDRE + BESS developer; strong revenue growth. | AN20: ROE/ROCE well below 20% threshold; interest coverage thin (~1.15x); policy-dependent, capital-intensive profile (same as Premier Energies). | AO20: ROE ~7.6-10.6%; ROCE ~2.7-8.4%; D/E ~0.5-0.86; P/E ~26-90x (date-dependent). | AP20: N/A - exclude/monitor only, fails core profitability gate. | AQ20: Verified 2026-07 (MarketsMojo/Screener). | AR20: 8.1499998 | AS20: 9.896106 | AT20: 8.2569044 | AU20: 0.05 | AW20: 45.607365 | AX20: 4.448248 | AY20: 50 | AZ20: 100 | BA20: 50 | BC20: OK | BD20: Avoid | BG20: Extreme Premium | BH20: Scored | BJ20: OK | BK20: ROE matches within tolerance (14.8% variance). | BQ20: 100 | BT20: 100
A21: 20 | B21: Atul Auto | C21: ATULAUTO.NS | D21: Consumer Cyclical | E21: Auto Manufacturers | F21: 13706356736 | G21: Research | H21: Fail | I21: 34 | J21: 0 | K21: 70 | L21: 100 | M21: Low priority - ROE well below threshold, near-flat revenue CAGR | N21: None | O21: Three-wheeler (auto rickshaw) manufacturer, Gujarat-based, ~4% domestic market share | P21: 33 | Q21: 6.6 | R21: 5.08 | S21: 22.831388 | T21: 8.6222023 | U21: 11.963101 | V21: 0.2 | W21: 2.4342615 | X21: 2 | Y21: 5 | Z21: Not started | AA21: Jul-2026 | AB21: Jan-2027 | AC21: 298.78527 | AD21: 495 | AE21: 373.48159 | AF21: -32.242128 | AG21: 0.91851098 | AH21: 9185.1098 | AI21: Research (Low priority) | AJ21: Watch | AK21: Early | AL21: See structured fields (Thesis / Risks / Valuation / Trigger / Sources) for detail. | AM21: Three-wheeler manufacturer, Gujarat-based. | AN21: ROE only 5.72% (3yr); rich valuation on weak returns; revenue CAGR near-flat. | AO21: P/E ~26-44x. | AP21: N/A - excluded, narrow moat, weak capital efficiency. | AQ21: Verified 2026-07 (Screener/MoneyWorks4Me). | AR21: 15.220001 | AS21: 10 | AT21: 24.538869 | AV21: 0.623 | AW21: 32.45072 | AX21: 5.988409 | AY21: 75 | AZ21: 9.8314053 | BA21: 75 | BC21: OK | BD21: Avoid | BG21: Overvalued | BH21: Scored | BJ21: Conflict | BK21: ROE conflict: automated engine shows 8.62, Financial Data sheet shows 5.72 (33.7% relative variance, threshold 15%). | BQ21: 9.8314053 | BT21: 9.8314053
A22: 21 | B22: Mahindra Holidays & Resorts India | C22: MHRIL.NS | D22: Consumer Cyclical | E22: Resorts & Casinos | F22: 47398080512 | G22: Research | H22: Conflict | I22: 10 | J22: 0 | K22: 45 | L22: 100 | M22: Monitor - Altman Z-score 0.83 (weakest of peers), Q4 profit fell 43% on impairment | N22: None | O22: Vacation-ownership (Club Mahindra) + Holiday Club Resorts (Nordic/EU); Mahindra Group subsidiary | P22: 62.7 | Q22: 8.36 | R22: 6.97 | S22: 42.887252 | T22: 8.8702679 | U22: 2.2334238 | V22: 1.2 | W22: 1.28984 | X22: 7.5 | Y22: -43 | Z22: Not started | AA22: Jul-2026 | AB22: Sep-2026 | AC22: 112.00769 | AD22: 230 | AE22: 140.00961 | AF22: -67.859904 | AG22: =IF(H22="Fail","Not Eligible (Failed Gate)",IF(J22="","Pending Score",IF(J22>=90,"10%",IF(J22>=80,"7.5%",IF(J22>=70,"5%","Watchlist only"))))) -> Watchlist only | AH22: =IFERROR(ROUND(VALUE(SUBSTITUTE(AG22,"%",""))/100*Dashboard!$B$11,0),"") | AI22: Research (Weak) | AJ22: Watch | AK22: Early | AL22: See structured fields (Thesis / Risks / Valuation / Trigger / Sources) for detail. | AM22: Vacation-ownership (Club Mahindra) + Holiday Club Resorts (Nordic/EU). | AN22: Q4 FY26 profit -43.1% YoY (Mauritius impairment + soft EU); ROCE decreasing; Altman Z-score only 0.83 (weakest of 8 peers) - financial-stability red flag. | AO22: P/E ~62.7x (98% premium to peer median). | AP22: Resolve Altman Z / balance-sheet-strength concern before any scoring. | AQ22: Verified 2026-07 (Screener/Tijori/Groww). | AR22: 3.43 | AS22: 8.972 | AT22: 40.819129 | AV22: -0.195 | AW22: 68.51895 | AX22: 6.093179 | AY22: 75 | AZ22: 100 | BA22: 75 | BC22: OK | BD22: Avoid | BG22: Significantly Overvalued | BH22: Confirmed Weak Fundamentals | BQ22: 100 | BT22: 100
A23: 22 | B23: Power Finance Corporation | C23: PFC.NS | D23: Financial Services | E23: Credit Services | F23: 1344131301376 | G23: Research | H23: Pass | I23: 33.333333 | J23: 30.928542 | K23: 50 | L23: 60 | M23: Blocked - PFC-REC merger integration pending, do not score standalone metrics | N23: PFC-REC merger (board-approved 28-Jun-2026, 88:100 swap) | O23: Maharatna PSU infra-finance NBFC lending to power-sector utilities; PFC-REC merger in progress | ROCE/Debt-Equity shown are mechanically computed (Tijori/StockViz) - not economically standard metrics for a deposit-funded bank / borrowings-funded NBFC balance sheet; included per request, interpret with that context. | P23: 6.5 | Q23: 0.43 | R23: 0.39 | T23: 14.933578 | U23: 10.26 | V23: 8.25 | W23: -0.40932717 | X23: 10 | Y23: 15 | Z23: Not started | AA23: Jul-2026 | AB23: Sep-2026 | AC23: 718.38509 | AD23: 423 | AE23: 897.98136 | AF23: 54.642711 | AG23: 1.8857283 | AH23: 18857.283 | AI23: Research (Blocked - Merger) | AJ23: Corporate action | AK23: Early | AL23: See structured fields (Thesis / Risks / Valuation / Trigger / Sources) for detail. | AM23: Maharatna PSU infra-finance NBFC lending to power-sector utilities. | AN23: PFC-REC merger (approved 28-Jun-2026) creates integration/dilution uncertainty; State DISCOM loan-book concentration. | AO23: ROE ~19.49%; P/E ~5.6-7.3x (deep discount to peer avg ~17-18x); dividend yield ~5%. | AP23: Merger integration must clear before scoring stabilizes. | AQ23: Verified 2026-07 (MarketsMojo/GuruFocus). | AR23: 78.500005 | AS23: 16.125162 | AT23: 11.439253 | AU23: 3.91 | AV23: 0.62 | AW23: 5.1885347 | AX23: 1.0116062 | AY23: 50 | AZ23: 40 | BA23: 50 | BC23: Missing EV/EBIT (EBIT <= 0) | BD23: Avoid | BG23: Undervalued | BH23: Scored | BJ23: Conflict | BK23: ROE conflict: automated engine shows 14.93, Financial Data sheet shows 19.49 (23.4% relative variance, threshold 15%). | BQ23: 40 | BT23: 40
A24: 23 | B24: ITC | C24: ITC.NS | D24: Consumer Defensive | E24: Tobacco | F24: 3543960125440 | G24: Research | H24: Pass | I24: 77 | J24: 48.917866 | K24: 80 | L24: 100 | M24: Monitor - Q4 FY26 profit fell 73% YoY on base effect, use FY figure for trend | N24: None | O24: Dominant cigarettes + FMCG (25+ brands) + paperboards/agri conglomerate; hotels demerged Jan-2025 | P24: 17.6 | Q24: 3.52 | R24: 2.71 | S24: 13.928897 | T24: 28.391125 | U24: 33.195647 | V24: 0.03 | W24: 4.5667924 | X24: 9.87 | Y24: 5 | Z24: Not started | AA24: Jul-2026 | AB24: Oct-2026 | AC24: 166.66995 | AD24: 289 | AE24: 208.33744 | AF24: -35.765324 | AG24: 5.9650922 | AH24: 59650.922 | AI24: Research | AJ24: Watch | AK24: Mature | AL24: See structured fields (Thesis / Risks / Valuation / Trigger / Sources) for detail. | AM24: Dominant cigarettes + FMCG + paperboards/agri conglomerate. | AN24: 5yr sales growth only 9.87% (poor) - cigarette-volume dependency, FMCG-Others scaling slowly; ongoing restructuring (Sresta/Wimco amalgamation) to watch. | AO24: 3yr ROE 35.2%; P/E ~17.6-19x; dividend yield ~5%; near debt-free; payout 74.5%. | AP24: Growth-catalyst check needed before promotion. | AQ24: Verified 2026-07 (Screener). | AR24: 16.58 | AS24: 5 | AT24: 12.565587 | AU24: 5.7 | AV24: -0.081 | AW24: 17.059711 | AX24: 4.887764 | AY24: 100 | AZ24: 1.0975072 | BA24: 100 | BC24: OK | BD24: Watch (Quality, Pricey) | BG24: Overvalued | BH24: Scored | BJ24: Conflict | BK24: ROE conflict: automated engine shows 28.39, Financial Data sheet shows 35.20 (19.3% relative variance, threshold 15%). | BQ24: 1.0975072 | BT24: 1.0975072
A25: 24 | B25: Eicher Motors | C25: EICHERMOT.NS | D25: Consumer Cyclical | E25: Auto Manufacturers | F25: 2022909542400 | G25: Research | H25: Pass | I25: 72 | J25: 35.754288 | K25: 80 | L25: 100 | M25: Monitor - rich valuation, EV portfolio gap flagged by analysts | N25: None | O25: Royal Enfield (global leader, mid-weight motorcycles) + VECV JV with AB Volvo (trucks/buses) | P25: 38 | Q25: 2.11 | R25: 1.95 | S25: 40.96722 | T25: 21.972897 | U25: 18.219516 | V25: 0.05 | W25: 1.7423949 | X25: 15.6 | Y25: 18 | Z25: Not started | AA25: Jul-2026 | AB25: Oct-2026 | AC25: 3045.886 | AD25: 7454 | AE25: 3807.3575 | AF25: -93.559442 | AG25: 4.3599127 | AH25: 43599.127 | AI25: Research | AJ25: Watch | AK25: Early | AL25: See structured fields (Thesis / Risks / Valuation / Trigger / Sources) for detail. | AM25: Royal Enfield (global mid-weight motorcycle leader) + VECV JV with AB Volvo. | AN25: Valuation stretched (P/E ~38-41x, 'somewhat overvalued' per MoneyWorks4Me); P/B ~8-9.6x. | AO25: Current ROE ~24%; near debt-free; revenue CAGR ~15.6% (vs ~13.4% industry median). | AP25: Same valuation-discipline check as RR Kabel before promotion. | AQ25: Verified 2026-07 (Screener/MoneyWorks4Me/Wisesheets). | AR25: 201.03998 | AS25: 15.484006 | AT25: 18.938308 | AU25: 1.11 | AV25: 0.275 | AW25: 36.656887 | AX25: 8.053834 | AY25: 100 | AZ25: 0.68253244 | BA25: 100 | BC25: OK | BD25: Hold | BG25: Significantly Overvalued | BH25: Scored | BJ25: OK | BK25: ROE matches within tolerance (8.4% variance). | BQ25: 0.68253244 | BT25: 0.68253244
A26: 25 | B26: CreditAccess Grameen | C26: CREDITACC.NS | D26: Financial Services | E26: Credit Services | F26: 248079564800 | G26: Research | H26: Conflict | I26: 35 | J26: 10.5 | K26: 55 | L26: 100 | M26: Active - confirm ROE/ROA recovery holds 2 more quarters vs FY27 guidance (16-20%) | N26: None | O26: India's largest MFI (Grameen Koota); diversifying into retail/individual/two-wheeler lending | ROCE/Debt-Equity shown are mechanically computed (Tijori/StockViz) - not economically standard metrics for a deposit-funded bank / borrowings-funded NBFC balance sheet; included per request, interpret with that context. | P26: 41.9 | Q26: 0.07 | R26: 0.07 | T26: 9.9160318 | U26: 14.811537 | V26: 2.96 | X26: 14 | Y26: 619 | Z26: Not started | AA26: Jul-2026 | AB26: Sep-2026 | AC26: 584.17538 | AD26: 1460 | AE26: 730.21923 | AF26: -112.0733 | AG26: =IF(H26="Fail","Not Eligible (Failed Gate)",IF(J26="","Pending Score",IF(J26>=90,"10%",IF(J26>=80,"7.5%",IF(J26>=70,"5%","Watchlist only"))))) -> Watchlist only | AH26: =IFERROR(ROUND(VALUE(SUBSTITUTE(AG26,"%",""))/100*Dashboard!$B$11,0),"") | AI26: Research (Recovery watch) | AJ26: Watch | AK26: Early | AL26: See structured fields (Thesis / Risks / Valuation / Trigger / Sources) for detail. | AM26: India's largest MFI (Grameen Koota); diversifying into retail/individual/two-wheeler lending. | AN26: Trailing 3yr ROE only 13.8% (below threshold) after FY26 MFI-sector stress (Karnataka delinquencies). | AO26: FY26 full-year ROA 2.7%/ROE 10.7%; Q4 FY26 recovered to ROA 4.4%/ROE 17.8%; GNPA improved to 3.17%; P/E ~41.9x. FY27 guidance ROE 16-20%. | AP26: Needs 1-2 more quarters of recovery confirmation vs guidance. | AQ26: Verified 2026-07 (Screener/company guidance/MOFSL). | AR26: 48.410001 | AS26: 10.510001 | AT26: 15.084058 | AV26: 0.184 | AW26: 31.989258 | AX26: 3.1633716 | AY26: 25 | AZ26: 40 | BA26: 25 | BC26: OK | BD26: Avoid | BG26: Significantly Overvalued | BH26: Scored | BJ26: OK | BK26: ROE matches within tolerance (7.3% variance). | BQ26: 40 | BT26: 40
A27: 26 | B27: Punjab National Bank | C27: PNB.NS | D27: Financial Services | E27: Banks - Regional | F27: 1197219774464 | G27: Research | H27: Fail | I27: 16.666667 | J27: 0 | K27: 70 | L27: 60 | M27: Low - PSU bank, improving but sub-scale vs SBI | N27: None | O27: India's 2nd-largest PSU bank; post-NPA-cycle turnaround story, govt-owned (Promoter 70.1%) | ROCE/Debt-Equity shown are mechanically computed (Tijori/StockViz) - not economically standard metrics for a deposit-funded bank / borrowings-funded NBFC balance sheet; included per request, interpret with that context. | P27: 7.3 | Q27: 0.74 | R27: 0.65 | T27: 12.207936 | U27: 15.27 | V27: 0.66 | W27: 56.419397 | X27: 9.8 | Y27: -46 | Z27: Not started | AA27: Jul-2026 | AB27: Oct-2026 | AC27: 378.9407 | AD27: 106 | AE27: 473.67588 | AF27: 78.008169 | AG27: 0.56555363 | AH27: 5655.5363 | AI27: Research | AJ27: Watch | AK27: Early | AL27: See structured fields (Thesis / Risks / Valuation / Trigger / Sources) for detail. | AM27: India's 2nd-largest PSU bank; post-NPA-cycle turnaround story. | AN27: ROE below SBI's and below 20% (non-bank) threshold; 5yr sales growth poor (9.8%). | AO27: ROE ~14.9%; ROA ~0.9-1.1%; P/E ~7.3-8x (cheap). | AP27: N/A - excluded vs SBI as better-quality PSU-bank exposure. | AQ27: Verified 2026-07 (Screener/GuruFocus/Univest). | AR27: 16 | AS27: 10.63082 | AT27: 29.604742 | AU27: 2.97 | AV27: 0.527 | AW27: 6.510625 | AX27: 0.7982926 | AY27: 60 | AZ27: 40 | BA27: 100 | BC27: Missing EV/EBIT (EBIT <= 0) | BD27: Avoid | BG27: Undervalued | BH27: Uncertain - Partial Data | BJ27: Conflict | BK27: ROE conflict: automated engine shows 12.21, Financial Data sheet shows 14.90 (18.1% relative variance, threshold 15%). | BQ27: 40 | BT27: 40
A28: 27 | B28: Coforge | C28: COFORGE.NS | D28: Technology | E28: Information Technology Services | F28: 668463136768 | G28: Deferred | H28: Conflict | I28: 79 | J28: 38.510113 | K28: 93 | L28: 100 | M28: High - resolvable via post-Encora quarterly filings | N28: Cigniti Technologies amalgamation (completed) | O28: IT services, post-Encora acquisition integration phase | P28: 37 | Q28: 0.4 | R28: 0.4 | S28: 28.176576 | T28: 16.070285 | U28: 21.089012 | V28: 0.7 | W28: 1.5748194 | X28: 35.9 | Y28: 91.6 | Z28: Not started | AA28: Jul-2026 | AB28: Oct-2026 | AC28: 575.62819 | AD28: 1464 | AE28: 719.53524 | AF28: -109.85769 | AG28: 2.7143636 | AH28: 27143.636 | AI28: Deferred | AJ28: Watch | AK28: Early | AL28: See structured fields (Thesis / Risks / Valuation / Trigger / Sources) for detail. | AM28: IT services + Encora acquisition-led growth. | AN28: Thesis Health Score revised down 83->71/100; Encora funded via ~20% equity dilution (Rs.17,032cr QIP) plus debt roughly tripling; PE-sponsor (Advent/Warburg) stake-sale overhang; same IT theme as TCS - cannot hold both under one-theme-per-core-slot rule. | AO28: P/E ~36-38x vs TCS ~18.6x (~2x premium). | AP28: 2 consecutive quarters of post-Encora integration proof, debt reduction, EPS accretion validated. | AQ28: Session review (multiple). | AR28: 44.500002 | AS28: 11.892143 | AT28: 16.169331 | AU28: 1.11 | AV28: 0.23 | AW28: 33.932583 | AX28: 5.317594 | AY28: 100 | AZ28: 2.506043 | BA28: 100 | BC28: OK | BD28: Watch (Quality, Pricey) | BG28: Significantly Overvalued | BH28: Scored | BQ28: 2.506043 | BT28: 2.506043
A29: 28 | B29: Premier Energies | C29: PREMIERENE.NS | D29: Technology | E29: Solar | F29: 494169686016 | G29: Deferred | H29: Conflict | I29: 72.5 | J29: 25.857678 | K29: 80 | L29: 100 | M29: Medium - structural (policy) + resolvable (FCF checkpoint) mixed gap | N29: None | O29: Solar cell/module manufacturing, capacity expansion phase | P29: 30.8 | Q29: 0.51 | R29: 0.5 | S29: 26.840238 | T29: 35.026478 | U29: 25.181249 | V29: 0.86 | W29: -3.3617461 | X29: 44 | Y29: 60 | Z29: Not started | AA29: Jul-2026 | AB29: Oct-2026 | AC29: 125.45201 | AD29: 1065 | AE29: 156.81501 | AF29: -598.27499 | AG29: 0.67680611 | AH29: 6768.0611 | AI29: Deferred (Policy-dependent) | AJ29: Watch | AK29: Early | AL29: See structured fields (Thesis / Risks / Valuation / Trigger / Sources) for detail. | AM29: Solar module/cell manufacturer; high ROE; policy-tailwind (ALMM/PLI) beneficiary. | AN29: D/E ~0.86 fails <0.3 threshold; FCF currently negative (~-Rs.17.4bn) from heavy capex; policy-dependent (structural, permanent risk tag). | AO29: PEG ~1.06 (passes); ROE ~42% (strong). | AP29: FCF-to-positive checkpoint, review quarterly. | AQ29: Session review. | AR29: 35.069999 | AS29: 25 | AT29: 4.4714859 | AU29: 0.14 | AW29: 31.223269 | AX29: 11.451939 | AY29: 50 | AZ29: 28.668474 | BA29: 50 | BC29: OK | BD29: Avoid | BG29: Extreme Premium | BH29: Scored | BQ29: 28.668474 | BT29: 28.668474
A30: 29 | B30: Star Health and Allied Insurance Company | C30: STARHEALTH.NS | D30: Financial Services | E30: Insurance - Life | F30: 358072942592 | G30: Deferred | H30: Pass | I30: 56.666667 | J30: 40.97819 | K30: 92 | L30: 60 | M30: High - resolvable via next 1-2 quarters underwriting data | N30: None | O30: Standalone health insurer, retail-focused | P30: 45 | Q30: 1.7 | R30: 1.61 | T30: 7.3760267 | U30: 11.65 | V30: 0.05 | W30: 5.1539981 | X30: 26.4 | Y30: -30 | Z30: Not started | AA30: Jul-2026 | AB30: Sep-2026 | AC30: 612.56296 | AD30: 587 | AE30: 765.7037 | AF30: 20.524087 | AG30: 2.9981522 | AH30: 29981.522 | AI30: Deferred (Weak ROE) | AJ30: Watch | AK30: Early | AL30: See structured fields (Thesis / Risks / Valuation / Trigger / Sources) for detail. | AM30: Health insurer; underwriting profitability recovering. | AN30: Retail claim settlement ratio only 92% (not 99%, which was actually renewal ratio - correction needed); solvency ratio (214%) not independently verified; durability vs medical inflation (12-13% expected 2026) and pending commission regulation untested. | AO30: Combined ratio 98.9% (Q3 FY26, improved from 102.1% YoY); renewal ratio 99%; loss/incurred claim ratio improved 71.8%->68.8%. | AP30: Awaiting 1-2 more quarters before candidate-pool promotion. | AQ30: Session review; Business Confidence = Moderate. | AR30: 9.4600004 | AS30: 10 | AT30: 80.941194 | AV30: 0.204 | AW30: 64.32875 | AX30: 4.706569 | AY30: 60 | AZ30: 40 | BA30: 75 | BC30: Missing EV/EBIT (EBIT <= 0) | BD30: Hold | BG30: Undervalued | BH30: Scored | BQ30: 40 | BT30: 40
A31: 30 | B31: Vikram Solar | C31: VIKRAMSOLR.NS | D31: Technology | E31: Solar | F31: 71626588160 | G31: Deferred | H31: Conflict | I31: 55 | J31: 40.551075 | K31: 40 | L31: 100 | M31: Blocked - understand NCLAT set-aside (29-Jun-2026) and reconcile D/E before further work | N31: NCLAT set aside NCLT Kolkata insolvency admission (29-Jun-2026) | O31: Solar PV module manufacturer + EPC/O&M; large order book (10.3GW, 2x FY25 capacity) | P31: 16.5 | Q31: 0.07 | R31: 0.07 | S31: 10.299382 | T31: 14.850273 | U31: 20.117923 | V31: 1.81 | W31: -1.1907463 | X31: 28.5 | Y31: 236 | Z31: Not started | AA31: Jul-2026 | AB31: Aug-2026 | AC31: 130.79777 | AD31: 189 | AE31: 163.49722 | AF31: -20.901141 | AG31: 0.68172729 | AH31: 6817.2729 | AI31: Deferred (Blocked - legal) | AJ31: Watch | AK31: Early | AL31: See structured fields (Thesis / Risks / Valuation / Trigger / Sources) for detail. | AM31: Solar PV module manufacturer + EPC/O&M; large order book (10.3GW). | AN31: MAJOR: NCLT insolvency case (set aside by NCLAT 29-Jun-2026, root cause unverified); D/E conflict (1.81x vs implied lower post-paydown); previously flagged as 'story over evidence' lapse. | AO31: P/E ~16.5x (cheap, 42% discount to peer median); ROE improved to 19.67% (2024) from 4.05% (2023); revenue CAGR 17-28.5%; Altman Z-score 3.87. | AP31: Insolvency matter fully understood AND D/E reconciled to primary filing before promotion out of Conflict. | AQ31: Verified 2026-07 (Screener/Tijori/ValueResearch/wwipl). | AR31: 13.589999 | AS31: 21.336001 | AT31: 12.0307 | AW31: 14.545254 | AX31: 2.2591374 | AY31: 25 | AZ31: 6.7885088 | BA31: 25 | BC31: OK | BD31: Hold | BG31: Overvalued | BH31: Scored | BQ31: 6.7885088 | BT31: 6.7885088
A32: 31 | B32: SANDUMA | C32: SANDUMA.NS | D32: Basic Materials | E32: Steel | F32: 100881326080 | G32: ML Screen | H32: Fail | I32: 85 | J32: 0 | K32: 70 | L32: 100 | M32: Monitor - cyclical commodity, capacity expansion approved | N32: None | O32: Metals & Mining (iron ore) | P32: 15.6 | Q32: 0.31 | R32: 0.3 | S32: 11.079086 | T32: 20.082024 | U32: 25.161829 | V32: 0.5 | W32: 8.9380565 | X32: 89 | Y32: 50 | Z32: Not started | AA32: Jul-2026 | AB32: Oct-2026 | AC32: 411.66067 | AD32: 220 | AE32: 514.57583 | AF32: 59.669695 | AG32: 7.0187549 | AH32: 70187.549 | AI32: ML Screen | AJ32: Watch | AK32: Early | AL32: See structured fields (Thesis / Risks / Valuation / Trigger / Sources) for detail. | AM32: N/A - excluded on cyclicality principle. | AN32: ML Alpha screen only, unverified against primary source; commodity-price-driven earnings. | AO32: Not independently verified. | AP32: N/A - excluded, doesn't fit quality-compounder bucket regardless of screen score. | AQ32: ML Alpha screen only (unverified). | AR32: 13.51 | AS32: 21.630607 | AT32: 38.088515 | AU32: 0.21 | AV32: 0.767 | AW32: 15.361214 | AX32: 3.1007948 | AY32: 100 | AZ32: 10.18781 | BA32: 100 | BC32: OK | BD32: Avoid | BG32: Undervalued | BH32: Scored | BQ32: 10.18781 | BT32: 10.18781
A33: 32 | B33: NMDC | C33: NMDC.NS | D33: Basic Materials | E33: Steel | F33: 751172911104 | G33: ML Screen | H33: Fail | I33: 79.5 | J33: 0 | K33: 75 | L33: 100 | M33: Monitor - PSU miner, iron ore price sensitive | N33: None | O33: Iron ore mining, PSU | P33: 10.2 | Q33: 0.29 | R33: 0.28 | S33: 9.2675257 | T33: 21.864179 | U33: 24.251045 | V33: 0.13 | W33: 2.2428993 | X33: 60.7 | Y33: 35 | Z33: Not started | AA33: Jul-2026 | AB33: Oct-2026 | AC33: 75.76803 | AD33: 88 | AE33: 94.710038 | AF33: 9.7878092 | AG33: 5.2862489 | AH33: 52862.489 | AI33: ML Screen | AJ33: Watch | AK33: Early | AL33: See structured fields (Thesis / Risks / Valuation / Trigger / Sources) for detail. | AM33: N/A - excluded on cyclicality principle. | AN33: Cyclical commodity business, earnings swing with iron ore prices. | AO33: P/E 10.2; ROE 23.4% (ML Alpha screen, statistically attractive but not IOS-fit). | AP33: N/A - excluded early in session. | AQ33: ML Alpha screen (unverified vs primary). | AR33: 8.5399999 | AS33: 13.709408 | AT33: 11.090168 | AU33: 4.18 | AV33: 0.618 | AW33: 10.004684 | AX33: 2.2012677 | AY33: 100 | AZ33: 6.267192 | BA33: 100 | BC33: OK | BD33: Avoid | BG33: Fair Value | BH33: Scored | BQ33: 6.267192 | BT33: 6.267192
A34: 33 | B34: Ashapura Minechem | C34: ASHAPURMIN.NS | D34: Basic Materials | E34: Other Industrial Metals & Mining | F34: 62048972800 | G34: ML Screen | H34: Fail | I34: 40 | J34: 0 | K34: 65 | L34: 100 | M34: Monitor - FY26 revenue nearly doubled, net debt declining | N34: None | O34: Metals & Mining (bentonite/bauxite) | P34: 15.6 | Q34: 0.39 | R34: 0.38 | S34: 17.360064 | T34: 24.404954 | U34: 15.099023 | V34: 0.69 | W34: 2.5042379 | X34: 98 | Y34: 40 | Z34: Not started | AA34: Jul-2026 | AB34: Oct-2026 | AC34: 463.60897 | AD34: 670 | AE34: 579.51122 | AF34: -12.085837 | AG34: 0.39064912 | AH34: 3906.4912 | AI34: ML Screen | AJ34: Watch | AK34: Early | AL34: See structured fields (Thesis / Risks / Valuation / Trigger / Sources) for detail. | AM34: N/A - excluded on cyclicality principle. | AN34: ML Alpha screen only, unverified against primary source. | AO34: Not independently verified. | AP34: N/A - excluded, same cyclicality principle as NMDC/SANDUMA. | AQ34: ML Alpha screen only (unverified). | AR34: 42.030001 | AS34: 25 | AT34: 13.788038 | AU34: 0.16 | AV34: 0.661 | AW34: 15.454437 | AX34: 3.7621703 | AY34: 100 | AZ34: 29.25814 | BA34: 100 | BC34: OK | BD34: Avoid | BG34: Overvalued | BH34: Scored | BQ34: 29.25814 | BT34: 29.25814
A35: 34 | B35: BLS International Services | C35: BLS.NS | D35: Industrials | E35: Specialty Business Services | F35: 97757110272 | G35: ML Screen | H35: Conflict | I35: 89.5 | J35: 100 | K35: 75 | L35: 100 | M35: Active - confirm FY27 govt contract renewal terms | N35: None | O35: Visa/govt-outsourcing services | P35: 15.3 | Q35: 0.44 | R35: 0.42 | S35: 13.833427 | T35: 24.668842 | U35: 23.078704 | V35: 0.1 | W35: 7.6337571 | X35: 36.7 | Y35: 35.1 | Z35: Not started | AA35: Jul-2026 | AB35: Oct-2026 | AC35: 424.70648 | AD35: 262 | AE35: 530.8831 | AF35: 55.253802 | AG35: 7.4304363 | AH35: 74304.363 | AI35: ML Screen (Active) | AJ35: Watch | AK35: Early | AL35: See structured fields (Thesis / Risks / Valuation / Trigger / Sources) for detail. | AM35: Visa/consular outsourcing services provider. | AN35: ROCE inconsistent across sources (28% vs 64%, large spread); management self-disclosed government-contract renewal uncertainty on Q4 call; FY27 growth guidance (20-25%) is a deceleration from FY26 actual; some trackers show P/E >1000x (likely low-base-year distortion). | AO35: ML screen: P/E 15.3, ROE 32.7%, F-Score 8 (looks clean on screen). | AP35: FY27 contract renewals confirmed and valuation reset before promotion. | AQ35: ML screen + deeper session research (conflicting). | AR35: 16.090001 | AS35: 24.708217 | AT35: 32.994599 | AU35: 1.24 | AV35: -0.247 | AW35: 14.763828 | AX35: 3.9686916 | AY35: 100 | AZ35: 5.1559758 | BA35: 100 | BC35: OK | BD35: Watch | BG35: Undervalued | BH35: Scored | BQ35: 5.1559758 | BT35: 5.1559758
A36: 35 | B36: eClerx Services | C36: ECLERX.NS | D36: Technology | E36: Information Technology Services | F36: 147534905344 | G36: ML Screen | H36: Conflict | I36: 89.5 | J36: 100 | K36: 70 | L36: 100 | M36: Monitor - ROCE-decline explanation, profit-quality check needed | N36: None | O36: BPM/analytics, IT-adjacent services | P36: 19.4 | Q36: 0.79 | R36: 0.75 | S36: 16.48774 | T36: 27.540796 | U36: 29.297859 | V36: 0.13 | W36: 5.2223566 | X36: 23 | Y36: 24.5 | Z36: Not started | AA36: Jul-2026 | AB36: Oct-2026 | AC36: 1784.9026 | AD36: 1400 | AE36: 2231.1282 | AF36: 28.143977 | AG36: 7.3560426 | AH36: 73560.426 | AI36: ML Screen | AJ36: Watch | AK36: Early | AL36: See structured fields (Thesis / Risks / Valuation / Trigger / Sources) for detail. | AM36: KPO/analytics services provider. | AN36: Tijori flags ROCE decreasing despite no significant capex (unexplained); lower depreciation rate inflating net profit; possible aggressive revenue recognition (receivables growing faster than sales, poor OCF conversion); rating fell Strong Buy(Jan-2026)->Sell(Jun-2026); theme overlaps with TCS (IT). | AO36: ML screen: P/E 19.4, ROE 29%, F-Score 8. | AP36: Resolve ROCE-decline explanation; document IT-theme exception before promotion. | AQ36: ML screen + Tijori (session review). | AR36: 78.440007 | AS36: 25 | AT36: 28.443756 | AU36: 0.03 | AV36: 0.409 | AW36: 20.43855 | AX36: 5.790129 | AY36: 100 | AZ36: 5.0041156 | BA36: 100 | BC36: OK | BD36: Watch | BG36: Undervalued | BH36: Scored | BQ36: 5.0041156 | BT36: 5.0041156
A37: 36 | B37: Sharda Cropchem | C37: SHARDACROP.NS | D37: Basic Materials | E37: Agricultural Inputs | F37: 82858508288 | G37: Data Hold | H37: Fail | I37: 58 | J37: 0 | K37: 35 | L37: 100 | M37: Blocked - reconcile FY26 revenue/PAT vs BSE filing and ROE-basis conflict before proceeding | N37: None | O37: Asset-light agrochemical registration/distribution platform, not a manufacturer | P37: 12 | Q37: 0.21 | R37: 0.21 | S37: 11.28155 | T37: 21.703961 | U37: 21.066641 | V37: 0.1 | W37: 1.9636664 | X37: 13 | Y37: 57 | Z37: Not started | AA37: Jul-2026 | AB37: Before further work | AC37: 543.23528 | AD37: 885 | AE37: 679.0441 | AF37: -35.248949 | AG37: 2.9549238 | AH37: 29549.238 | AI37: Data Hold | AJ37: FY26 Reconciliation | AK37: Unresolved | AL37: See structured fields (Thesis / Risks / Valuation / Trigger / Sources) for detail. | AM37: Agrochemical (generic crop-protection) exporter. | AN37: TWO unresolved conflicts: (1) 3yr avg ROE 13.6% (Screener) vs 24.2% (ML screen), explainable by down-cycle-vs-recovery-year averaging; (2) FY26 revenue/profit figures disagree materially across sources (Rs.5,268cr/Rs.681cr vs Rs.4,379cr/Rs.304cr for same fiscal year, ~20-120% apart) - UNRESOLVED. Europe ~45% revenue concentration; 166-day receivables; pesticide-registration regulatory risk. | AO37: Not usable until conflicts resolved. | AP37: Confirm FY26 revenue/profit directly against Sharda's BSE filing before any scoring. | AQ37: Screener vs ML screen (conflicting); Data Confidence gate not passed. | AR37: 75.490002 | AS37: 20.316037 | AT37: 8.9951529 | AU37: 2.04 | AV37: 0.559 | AW37: 12.165851 | AX37: 2.641616 | AY37: 100 | AZ37: 0 | BA37: 100 | BC37: OK | BD37: Avoid | BG37: Overvalued | BH37: Scored | BQ37: 0 | BT37: 0
A38: 37 | B38: Sterlite Technologies | C38: STLTECH.NS | D38: Technology | E38: Communication Equipment | F38: 276219166720 | I38: 10 | J38: 3.3737507 | L38: 100 | T38: 2.4691358 | U38: 7.5289575 | AC38: 71.030906 | AE38: 88.788633 | AF38: -505.37029 | AR38: 1.22 | AS38: 5 | AT38: 72.777568 | AV38: 1.417 | AW38: 440.57376 | AX38: 11.555909 | AY38: 75 | AZ38: 32.524985 | BA38: 75 | BC38: OK | BD38: Avoid | BG38: Extreme Premium | BH38: Confirmed Weak Fundamentals | BQ38: 32.524985 | BT38: 32.524985
A39: 38 | B39: Garware Hi-Tech Films | C39: GRWRHITECH.NS | D39: Basic Materials | E39: Specialty Chemicals | F39: 162603532288 | I39: 34.5 | J39: 17.2161 | L39: 100 | S39: 41.453574 | T39: 12.733796 | U39: 14.329116 | W39: 0.70540957 | AC39: 1181.983 | AE39: 1477.4787 | AF39: -373.7124 | AG39: 2.0993479 | AH39: 20993.479 | AR39: 145.3 | AS39: 12.34539 | AT39: 10.16847 | AU39: 0.18 | AV39: 0.667 | AW39: 48.169304 | AX39: 6.121383 | AY39: 100 | AZ39: 0.19652431 | BA39: 100 | BC39: OK | BD39: Avoid | BG39: Extreme Premium | BH39: Scored | BQ39: 0.19652431 | BT39: 0.19652431
A40: 39 | B40: Cupid | C40: CUPID.NS | D40: Consumer Defensive | E40: Household & Personal Products | F40: 298218848256 | I40: 79.5 | J40: 38.092934 | L40: 100 | S40: 266.26154 | T40: 24.008853 | U40: 23.708938 | W40: 0.072122825 | AC40: 5.6464484 | AE40: 7.0580605 | AF40: -3042.223 | AG40: 3.483817 | AH40: 34838.17 | AR40: 0.84000003 | AS40: 25 | AT40: 8.402453 | AV40: 0.288 | AW40: 264.0238 | AX40: 66.06493 | AY40: 75 | AZ40: 4.1687204 | BA40: 75 | BC40: OK | BD40: Watch (Quality, Pricey) | BG40: Extreme Premium | BH40: Scored | BQ40: 4.1687204 | BT40: 4.1687204
...

Sheet Financial Data
A1: Company | B1: Quarter | C1: Revenue | D1: Revenue Growth % | E1: EBITDA | F1: EBITDA Margin % | G1: Net Profit | H1: EPS | I1: EPS Growth % | J1: Operating Cash Flow | K1: Free Cash Flow | L1: FCF Yield % | M1: ROE % | N1: ROCE % | O1: ROA % | P1: Debt/Equity | Q1: Interest Coverage | R1: Current Ratio | S1: P/E | T1: PEG | U1: PEGY | V1: EV/EBIT | W1: P/B | X1: Dividend Yield % | Y1: Notes
